Workbook

Sheet About
A1: PoFDCtAE Perc of Fuel Demand Changes that Affect Exports | B1: Rhode Island | C1: 46260
A2: State code: | B2: =VLOOKUP($B$1,Keys!$B$2:$C$49,2,FALSE) -> RI
A3: Sources: | B3: Balanced initial (2025) production, imports and exports - the calc basis
B4: Provides: the quantities the export routing actually operates on - Initial BAU Fuel Production Imports and Exports, the balanced 2025 values (INITIAL TIME = 2025, verified in plcy-schd/IT/IT.csv). Every derived diagonal comes from this tab.
B5: Publisher: Energy Innovation, EPS state models (this repo's 48-state sweep)
B6: Title: climate-0825.csv sweep export, variable 'BAU Fuel Production Imports and Exports', 2025 column
B7: Year: 2026
B8: state-eps-code/run-all/climate-0825.csv
B9: Table / sheet used: 3,024 rows (48 states x 21 fuels x 3 parts) - embedded verbatim on tab Balanced_2025.
B10: Accessed / handling: extracted 2026-08-26 by _stage_pofdctae_inputs.py; source and staged sha256 on the tab. Single run in the file (US_ClimateAmbition); the variable is BAU-side, so it is policy-independent.
B11: Caveats and limits: model-derived, NOT a primary source. Must be re-staged after any BFPIaE, energy-use or FPIEBP redeploy. climate-0825 is post-BFPaT-year-fix, so it is the correct vintage as of this build. Also: no AK/HI rows exist - the sweep tree is 48 states - so those two keep the national file.
B13: Per-state raw BAU fuel production, imports and exports (comparison only)
B14: Provides: the raw published series underlying the balanced values, embedded so the difference between raw and balanced is visible without leaving the workbook. NOT the calc basis.
B15: Publisher: Energy Innovation, state-eps-data repository
B16: Title: BFPIaE BAU Fuel Production Imports and Exports (48 state file sets)
... B31: Caveats and limits: the national file's product->crude off-diagonal entries (gasoline 0.925, diesel 0.733, jet 0.898, HFO 0.50, LPG 0.45) were zeroed across eps-us and all 50 state folders on 2026-08-25 (state-eps-data 509bc03d38), matching the .mdl-side removal of the crude neutralizer. This build inherits that; it does not re-introduce them. The national diagonals themselves are e/production (primary fuels) or e/(e+use) (secondary products) on a national BFPIaE vintage that differs from the current one - do not read them as a target for the state values.
A34: Notes:
A35: Rule | B35: diagonal[state, fuel] = MIN(1, MAX(0, E - I) / (MAX(0, E - I) + (P + I - E))), on the balanced initial (2025) values; 0 where the denominator is 0. In words: the share of a state's outflows that is genuinely redirectable, netting imports out of exports so a pipeline corridor is not credited with an export channel it cannot supply. Off-diagonals are 0. The crude->crude diagonal is held at the national 1.0 (see 'Crude' below).
A36: Equivalent form | B36: Whenever E > I the denominator equals P exactly - domestic use cancels - so the rule is net exports as a share of production, MAX(0, E - I) / P. Verified on all 576 tradeable cells with 0 violations; the identity is a live check row on the Checks tab. It follows that the rule is NOT bounded above by construction: any cell with 0 < P < E - I would exceed 1. No such cell exists in the current data, and the MIN(1, ...) makes the bound explicit rather than assumed.
A37: Why balanced, not raw (decision 2026-08-26) | B37: The routing operates on the model's balanced quantities, not the published series. Raw and balanced diverge most in exactly the states this variable is meant to fix: FL crude 0.325 raw vs 0.508 balanced, NE 0.613 vs 0.924, TX 0.183 vs 0.000. Same precedent as MPIiFE. The balanced basis is a single year, so no averaging window is needed.
A38: Crude (decision 2026-08-26) | B38: The crude->crude diagonal is held at the national 1.0 for every state rather than derived. Note the residual this leaves: with the product->crude shortcut zeroed, crude->crude is the only live routing channel, and CA IL WA NJ PA all have zero balanced crude exports with large crude imports - so a refining-driven crude-use drop routes 100% into crude exports from states that export none. FL and NE do not refine, so their gates are unaffected. Flagged for review alongside the production-backed export-headroom fix, which is NOT in the state model as of this build (run-all/FL/EPS.mdl:37653 still reads Initial BAU exports x MPIiFE, and MPIiFE is back at the national 999).
A39: State selector | B39: About!B1 holds the active state NAME; About!B2 derives the code. The output tab shows the active state's matrix; Calcs holds all 48 states, because a cross-state view is needed to sanity-check the distribution.
A40: Scope | B40: 48 conterminous states. AK and HI have PoFDCtAE and BFPIaE folders but are absent from the sweep tree, so no balanced values exist for them; they keep the national file. Computing them from raw BFPIaE is the fallback if coverage is wanted.
A41: Plan and review | B41: docs/plans/pofdctae-state-basis.md holds the build plan, the review of the 2026-08-26 handoff docs, the gate definitions and the open residuals. Findings: docs/findings/isic06-phantom-export-output-2026-08-24.md.
A43: Provenance:
B44: National layout and diagonals read at build time from eps-us/InputData/fuels/PoFDCtAE/PoFDCtAE.csv (sha256 02a6d970a693429d924982b5c5ff193722060b06bfe2f98776a904456959077e) into Keys!F:I.
B45: Staged inputs: raw_bfpiae_2024_2026.csv sha256 2456f5adb9c6399115ecdcb62daa7fbb30dacdd7949513ec915ca29f28ad795a; balanced_fpiae_2025.csv sha256 39d8b2881e397e54cbdb3701c2ff1800a25602d4c247ebcc689d3f1b73ebaf50.
B46: Built 2026-08-26 by outputs/PoFDCtAE/_build_pofdctae_workbook.py from _stage_pofdctae_inputs.py output.

Sheet Keys
A1: category | B1: key | C1: value | D1: description | F1: pofdctae_label | G1: balanced_label | H1: national_diagonal | I1: mode
A2: state | B2: Alabama | C2: AL | D2: state name -> code (About!B2 VLOOKUPs this block) | F2: electricity (not used in this variable) | H2: 0 | I2: zero
A3: state | B3: Arkansas | C3: AR | D3: state name -> code (About!B2 VLOOKUPs this block) | F3: hard coal | G3: hard coal | H3: 0.13753988 | I3: rule
A4: state | B4: Arizona | C4: AZ | D4: state name -> code (About!B2 VLOOKUPs this block) | F4: natural gas | G4: natural gas | H4: 0.19083918 | I4: rule
A5: state | B5: California | C5: CA | D5: state name -> code (About!B2 VLOOKUPs this block) | F5: nuclear | H5: 0 | I5: zero
A6: state | B6: Colorado | C6: CO | D6: state name -> code (About!B2 VLOOKUPs this block) | F6: hydro (is not a fuel) | H6: 0 | I6: zero
A7: state | B7: Connecticut | C7: CT | D7: state name -> code (About!B2 VLOOKUPs this block) | F7: wind (is not a fuel) | H7: 0 | I7: zero
A8: state | B8: Delaware | C8: DE | D8: state name -> code (About!B2 VLOOKUPs this block) | F8: solar (is not a fuel) | H8: 0 | I8: zero
A9: state | B9: Florida | C9: FL | D9: state name -> code (About!B2 VLOOKUPs this block) | F9: biomass | G9: biomass | H9: 0.74947425 | I9: rule
A10: state | B10: Georgia | C10: GA | D10: state name -> code (About!B2 VLOOKUPs this block) | F10: petroleum gasoline | G10: petroleum gasoline | H10: 0.075004052 | I10: rule
A11: state | B11: Iowa | C11: IA | D11: state name -> code (About!B2 VLOOKUPs this block) | F11: petroleum diesel | G11: petroleum diesel | H11: 0.26691052 | I11: rule
A12: state | B12: Idaho | C12: ID | D12: state name -> code (About!B2 VLOOKUPs this block) | F12: biofuel gasoline | G12: biofuel gasoline | H12: 0.087213884 | I12: rule
A13: state | B13: Illinois | C13: IL | D13: state name -> code (About!B2 VLOOKUPs this block) | F13: biofuel diesel | G13: biofuel diesel | H13: 0.058642381 | I13: rule
A14: state | B14: Indiana | C14: IN | D14: state name -> code (About!B2 VLOOKUPs this block) | F14: jet fuel or kerosene | G14: jet fuel or kerosene | H14: 0.10155994 | I14: rule
A15: state | B15: Kansas | C15: KS | D15: state name -> code (About!B2 VLOOKUPs this block) | F15: heat (not used in this variable) | H15: 0 | I15: zero
A16: state | B16: Kentucky | C16: KY | D16: state name -> code (About!B2 VLOOKUPs this block) | F16: geothermal (is not a fuel) | H16: 0 | I16: zero
A17: state | B17: Louisiana | C17: LA | D17: state name -> code (About!B2 VLOOKUPs this block) | F17: lignite | G17: lignite | H17: 0 | I17: rule
A18: state | B18: Massachusetts | C18: MA | D18: state name -> code (About!B2 VLOOKUPs this block) | F18: crude oil | G18: crude oil | H18: 1 | I18: hold
A19: state | B19: Maryland | C19: MD | D19: state name -> code (About!B2 VLOOKUPs this block) | F19: heavy fuel oil | G19: heavy or residual fuel oil | H19: 0.49914171 | I19: rule
A20: state | B20: Maine | C20: ME | D20: state name -> code (About!B2 VLOOKUPs this block) | F20: LPG propane or butane | G20: LPG propane or butane | H20: 0.54955999 | I20: rule
A21: state | B21: Michigan | C21: MI | D21: state name -> code (About!B2 VLOOKUPs this block) | F21: municipal solid waste | H21: 0 | I21: zero
A22: state | B22: Minnesota | C22: MN | D22: state name -> code (About!B2 VLOOKUPs this block) | F22: hydrogen | H22: 0 | I22: zero
A23: state | B23: Missouri | C23: MO | D23: state name -> code (About!B2 VLOOKUPs this block)
A24: state | B24: Mississippi | C24: MS | D24: state name -> code (About!B2 VLOOKUPs this block)
A25: state | B25: Montana | C25: MT | D25: state name -> code (About!B2 VLOOKUPs this block)
A26: state | B26: North Carolina | C26: NC | D26: state name -> code (About!B2 VLOOKUPs this block)
A27: state | B27: North Dakota | C27: ND | D27: state name -> code (About!B2 VLOOKUPs this block)
A28: state | B28: Nebraska | C28: NE | D28: state name -> code (About!B2 VLOOKUPs this block)
A29: state | B29: New Hampshire | C29: NH | D29: state name -> code (About!B2 VLOOKUPs this block)
A30: state | B30: New Jersey | C30: NJ | D30: state name -> code (About!B2 VLOOKUPs this block)
A31: state | B31: New Mexico | C31: NM | D31: state name -> code (About!B2 VLOOKUPs this block)
A32: state | B32: Nevada | C32: NV | D32: state name -> code (About!B2 VLOOKUPs this block)
A33: state | B33: New York | C33: NY | D33: state name -> code (About!B2 VLOOKUPs this block)
A34: state | B34: Ohio | C34: OH | D34: state name -> code (About!B2 VLOOKUPs this block)
... A49: state | B49: Wyoming | C49: WY | D49: state name -> code (About!B2 VLOOKUPs this block)
A51: constant | B51: zero | C51: 0 | D51: structural-zero value; comparison constant
A52: constant | B52: one | C52: 1 | D52: the MIN() ceiling on every diagonal, and the crude hold value
A53: constant | B53: initial_year | C53: 2025 | D53: INITIAL TIME of the state models (plcy-schd/IT/IT.csv) - the routing operates on the balanced 2025 values, so the diagonal is derived from them
A54: constant | B54: sep | C54: | | D54: separator used to build lookup keys (state|part|fuel)
A55: constant | B55: part_production | C55: production | D55: FPIaE part label
...

Sheet Methodology
A1: Methodology
A3: Purpose | B3: State-specific values for PoFDCtAE, the matrix deciding how much of a fuel demand drop is absorbed by higher exports instead of lower production and imports. All 50 state folders ship the national matrix byte-for-byte, so every state inherits the US export-routing assumption. At national scale that is the intended design; at state scale it credits export revenue to extraction industries a state does not have (FL gained a +$9.1B-by-2050 phantom oil and gas industry under US_ClimateAmbition).
A5: Rule | B5: diagonal = MIN(1, MAX(0, E - I) / (MAX(0, E - I) + (P + I - E))), 0 where the denominator is 0, on the balanced initial (2025) values. Netting imports out of exports is what makes the national concept transferable: it separates a state that genuinely ships fuel out from one that is a pipeline corridor. Off-diagonals are 0. Structural-zero rows and columns (electricity, heat, nuclear, hydro, wind, solar, geothermal, MSW, hydrogen) stay 0.
A7: Equivalent form and its consequence | B7: Whenever E > I the denominator equals P exactly, so the rule is net exports as a share of production. Verified on all 576 tradeable cells, 0 violations, and asserted as a live check row. Two consequences: domestic use does no work in the denominator, and the rule is NOT bounded above by construction - a cell with 0 < P < E - I would exceed 1. None exists today; the MIN(1, ...) makes the bound explicit and currently never binds.
A9: Why balanced, not raw (decision 2026-08-26) | B9: The routing operates on the model's balanced quantities, not the published series. EPS balances raw BFPIaE against BAU energy use first (FPIEBP priorities: imports 1, exports 2, production 3). 113 of 576 tradeable cells move by more than 0.05 between bases, including all three validation-gate states: FL crude 0.325 raw vs 0.508 balanced, NE 0.613 vs 0.924, TX 0.183 vs 0.000. Same precedent as MPIiFE. The balanced basis is a single year (INITIAL TIME = 2025), so the 3-year averaging window an earlier draft proposed - to dodge NE's raw 2024 zeros - is unnecessary; the balancer already resolves them (NE crude comes through at 0.924, not 0).
A11: Rejected: production share of supply | B11: An earlier draft set the diagonal to P/(P+I). Rejected on the data: it returns 1.000 wherever a state has any production and no imports, which is FL crude exactly - reviving the phantom channel in the headline example rather than closing it. It also measures where supply comes from rather than whether an export outlet exists.
A13: Crude oil (decision 2026-08-26) | B13: Held at the national 1.0 for every state rather than derived. Residual to be aware of: the product->crude off-diagonals were zeroed on 2026-08-25 across eps-us and all 50 state folders, so crude->crude is now the only live routing channel, and CA IL WA NJ PA all have zero balanced crude exports with large crude imports - a refining-driven crude-use drop there routes 100% into crude exports from states that export none. FL and NE do not refine, so ChangeUse[crude] is about 0 and their gates are unaffected. The production-backed export-headroom fix that would bound this is NOT in the state model as of this build.
A15: Derivation chain | B15: Balanced_2025 (embedded sweep extract, keyed state|part|fuel) -> Calcs section 1 INDEX/MATCH lookups of P, I, E per state x fuel -> use, redirectable, denominator, rule diagonal, applied diagonal -> Calcs section 2 reads the About!B1 state's 21 rows back out -> output tab PoFDCtAE places them on the diagonal of a 21x21 matrix of zeros. Raw_BFPIaE feeds only the comparison columns (P through S), never the applied value.
A17: Distribution | B17: 133 of 576 tradeable cells are nonzero (23%); all inside [0,1]. Thirteen states go entirely to zero - AZ GA ID MA MD ME NC NV NY OR RI SC VT - the intended result for consumer and pass-through states. Two values worth knowing rather than fixing: biomass is 0.000 in all 48 states because no state's balanced BFPIaE carries a biomass export row (national 0.749), and LA lignite is exactly 1.000 because LA produces lignite purely for export (production = exports, domestic use 0).
A19: Scope | B19: 48 conterminous states. AK and HI have PoFDCtAE and BFPIaE folders but are not in the sweep tree, so no balanced values exist; they keep the national file.
A21: Refresh procedure | B21: After any BFPIaE / energy-use / FPIEBP redeploy or a new sweep: re-run _stage_pofdctae_inputs.py against the newest sweep CSV, re-run _build_pofdctae_workbook.py, confirm every Checks row reads PASS, and re-run qc/pofdctae_replica_qc.py. The national labels and diagonals are read from eps-us at build time, so a national-file change flows through without editing this script.
A23: Validation gates (before deploy) | B23: Run against the state .mdl as it stands. (1) FL ClimateAmbition: Change in Domestic Output by ISIC Code[ISIC 06] about $0.0B through 2050 - but re-measure the pre-change baseline on climate-0825, since zeroing the shortcut on 08-25 may already have removed most of it. (2) TX ClimateAmbition as a no-change control, with the caveat that TX's gas and product diagonals move a lot (gas 0.531, gasoline 0.744) and its crude diagonal is held at 1.0, so a large TX shift is a question rather than an automatic fail. (3) NE ClimateAmbition: crude dP + dI - dE - dU = 0 every year and crude production intact. (4) Hard invariants across all 48 written CSVs.
A25: QC status | B25: Built 2026-08-26, NOT deployed. All 13 Checks rows PASS under Excel COM CalculateFullRebuild. Independent Python replica (qc/pofdctae_replica_qc.py, written from the plan rather than the builder): 576 tradeable cells, worst abs diff 0.000e+00, plus 432 structural-zero rows asserted 0. Staging fidelity re-checked by re-reading climate-0825.csv directly, 3,024 cells, worst relative diff 0.000e+00 - the workbook and the replica do not share one read path. Selector flip across six states clean. Output layout byte-matches eps-us. 48 exported CSVs: 21,168 cells, all in [0,1], off-diagonals zero, crude column clean, largest row sum 1.000000. workbook-qc family 1: 0 findings (qc/WorkbookQCResults_PoFDCtAE.xlsx, coverage ledger filled). NOT covered: families 2-3 run against deployed CSVs (deferred to deploy time), and nothing here proves the matrix produces the intended run results - see the validation gates above.

Sheet Raw_BFPIaE
A1: Raw BFPIaE 2024-2026 - embedded verbatim from state-eps-data (COMPARISON ONLY; the calc uses Balanced_2025)
A2: Source: state-eps-data/<ST>/fuels/BFPIaE/BFPIaE-{production,imports,exports}.csv, 48 states, accessed 2026-08-26
A3: Staged by _stage_pofdctae_inputs.py -> _staging/raw_bfpiae_2024_2026.csv (3024 rows; sha256 2456f5adb9c6399115ecdcb62daa7fbb30dacdd7949513ec915ca29f28ad795a)
A4: Handling: the 2024, 2025 and 2026 columns extracted verbatim; no value changes. Column G is a workbook-computed 3-year mean.
A5: Column headings below are plain-English; the staged file's own column names are state, part, fuel, value_2024, value_2025, value_2026. 'part' is the flow: production / imports / exports.
A6: CAVEAT: raw is NOT the basis the routing operates on. The calc uses Balanced_2025; this tab feeds only the comparison columns on Calcs (see Methodology).
A8: State | B8: Which flow (produced / brought in / shipped out) | C8: Fuel | D8: 2024, BTU | E8: 2025, BTU | F8: 2026, BTU | G8: Average of the three years to the left | H8: Lookup key (state + flow + fuel)
A9: AL | B9: production | C9: electricity (not used in this variable) | D9: 0 | E9: 0 | F9: 0 | G9: =AVERAGE($D9:$F9) -> 0 | H9: =$A9&Keys!$C$54&$B9&Keys!$C$54&$C9 -> AL|production|electricity (not used in this variable)
A10: AL | B10: production | C10: hard coal | D10: 294838000000000 | E10: 294838000000000 | F10: 294846000000000 | G10: =AVERAGE($D10:$F10) -> 2.9484067e+14 | H10: =$A10&Keys!$C$54&$B10&Keys!$C$54&$C10 -> AL|production|hard coal
A11: AL | B11: production | C11: natural gas | D11: 76628100000000 | E11: 76628100000000 | F11: 75748300000000 | G11: =AVERAGE($D11:$F11) -> 7.6334833e+13 | H11: =$A11&Keys!$C$54&$B11&Keys!$C$54&$C11 -> AL|production|natural gas
A12: AL | B12: production | C12: nuclear | D12: 0 | E12: 0 | F12: 0 | G12: =AVERAGE($D12:$F12) -> 0 | H12: =$A12&Keys!$C$54&$B12&Keys!$C$54&$C12 -> AL|production|nuclear
A13: AL | B13: production | C13: hydro (is not a fuel) | D13: 0 | E13: 0 | F13: 0 | G13: =AVERAGE($D13:$F13) -> 0 | H13: =$A13&Keys!$C$54&$B13&Keys!$C$54&$C13 -> AL|production|hydro (is not a fuel)
A14: AL | B14: production | C14: wind (is not a fuel) | D14: 0 | E14: 0 | F14: 0 | G14: =AVERAGE($D14:$F14) -> 0 | H14: =$A14&Keys!$C$54&$B14&Keys!$C$54&$C14 -> AL|production|wind (is not a fuel)
A15: AL | B15: production | C15: solar (is not a fuel) | D15: 0 | E15: 0 | F15: 0 | G15: =AVERAGE($D15:$F15) -> 0 | H15: =$A15&Keys!$C$54&$B15&Keys!$C$54&$C15 -> AL|production|solar (is not a fuel)
A16: AL | B16: production | C16: biomass | D16: 13897400000000 | E16: 13897400000000 | F16: 13897400000000 | G16: =AVERAGE($D16:$F16) -> 13897400000000 | H16: =$A16&Keys!$C$54&$B16&Keys!$C$54&$C16 -> AL|production|biomass
A17: AL | B17: production | C17: petroleum gasoline | D17: 137908000000000 | E17: 137908000000000 | F17: 134565000000000 | G17: =AVERAGE($D17:$F17) -> 1.3679367e+14 | H17: =$A17&Keys!$C$54&$B17&Keys!$C$54&$C17 -> AL|production|petroleum gasoline
A18: AL | B18: production | C18: petroleum diesel | D18: 81574700000000 | E18: 81574700000000 | F18: 79597500000000 | G18: =AVERAGE($D18:$F18) -> 8.0915633e+13 | H18: =$A18&Keys!$C$54&$B18&Keys!$C$54&$C18 -> AL|production|petroleum diesel
A19: AL | B19: production | C19: biofuel gasoline | D19: 0 | E19: 0 | F19: 0 | G19: =AVERAGE($D19:$F19) -> 0 | H19: =$A19&Keys!$C$54&$B19&Keys!$C$54&$C19 -> AL|production|biofuel gasoline
A20: AL | B20: production | C20: biofuel diesel | D20: 6007590000000 | E20: 6007590000000 | F20: 7136190000000 | G20: =AVERAGE($D20:$F20) -> 6383790000000 | H20: =$A20&Keys!$C$54&$B20&Keys!$C$54&$C20 -> AL|production|biofuel diesel
... A3032: WY | B3032: exports | C3032: hydrogen | D3032: 0 | E3032: 953160000000 | F3032: 642847000000 | G3032: =AVERAGE($D3032:$F3032) -> 5.3200233e+11 | H3032: =$A3032&Keys!$C$54&$B3032&Keys!$C$54&$C3032 -> WY|exports|hydrogen

Sheet Balanced_2025
A1: Balanced initial (2025) BAU Fuel Production Imports and Exports - THE CALC BASIS (equals the model's Initial values; INITIAL TIME = 2025)
A2: Source: state-eps-code/run-all/climate-0825.csv (48-state sweep, run 2026-08-25 20:32), variable 'BAU Fuel Production Imports and Exports', 2025 column, accessed 2026-08-26
A3: Source sha256 a0ca0b7a8b99ca0677af03c4d0680c6b7d770826aa1ea744758eed4b9eb6a584
A4: Staged _staging/balanced_fpiae_2025.csv sha256 39d8b2881e397e54cbdb3701c2ff1800a25602d4c247ebcc689d3f1b73ebaf50 (3024 rows = 48 states x 21 fuels x 3 parts)
A5: These equal the model's Initial BAU FPIaE (INITIAL TIME = 2025). BAU-side, so policy-independent; re-stage after any BFPIaE / energy-use / FPIEBP redeploy.
A6: Column headings below are plain-English; the staged file's own column names are state, part, fuel, value_2025. 'part' is the flow: production / imports / exports.
A8: State | B8: Which flow (produced / brought in / shipped out) | C8: Fuel | D8: 2025, BTU the value the calculation uses | E8: Lookup key (state + flow + fuel)
A9: AL | B9: production | C9: electricity | D9: 0 | E9: =$A9&Keys!$C$54&$B9&Keys!$C$54&$C9 -> AL|production|electricity
A10: AL | B10: imports | C10: electricity | D10: 0 | E10: =$A10&Keys!$C$54&$B10&Keys!$C$54&$C10 -> AL|imports|electricity
A11: AL | B11: exports | C11: electricity | D11: 0 | E11: =$A11&Keys!$C$54&$B11&Keys!$C$54&$C11 -> AL|exports|electricity
A12: AL | B12: production | C12: hard coal | D12: 294838000000000 | E12: =$A12&Keys!$C$54&$B12&Keys!$C$54&$C12 -> AL|production|hard coal
A13: AL | B13: imports | C13: hard coal | D13: 75813100000000 | E13: =$A13&Keys!$C$54&$B13&Keys!$C$54&$C13 -> AL|imports|hard coal
A14: AL | B14: exports | C14: hard coal | D14: 45989100000000 | E14: =$A14&Keys!$C$54&$B14&Keys!$C$54&$C14 -> AL|exports|hard coal
A15: AL | B15: production | C15: natural gas | D15: 76628100000000 | E15: =$A15&Keys!$C$54&$B15&Keys!$C$54&$C15 -> AL|production|natural gas
A16: AL | B16: imports | C16: natural gas | D16: 4.75849e+15 | E16: =$A16&Keys!$C$54&$B16&Keys!$C$54&$C16 -> AL|imports|natural gas
A17: AL | B17: exports | C17: natural gas | D17: 4.11261e+15 | E17: =$A17&Keys!$C$54&$B17&Keys!$C$54&$C17 -> AL|exports|natural gas
A18: AL | B18: production | C18: nuclear | D18: 0 | E18: =$A18&Keys!$C$54&$B18&Keys!$C$54&$C18 -> AL|production|nuclear
A19: AL | B19: imports | C19: nuclear | D19: 445614000000000 | E19: =$A19&Keys!$C$54&$B19&Keys!$C$54&$C19 -> AL|imports|nuclear
A20: AL | B20: exports | C20: nuclear | D20: 0 | E20: =$A20&Keys!$C$54&$B20&Keys!$C$54&$C20 -> AL|exports|nuclear
... A3032: WY | B3032: exports | C3032: hydrogen | D3032: 953160000000 | E3032: =$A3032&Keys!$C$54&$B3032&Keys!$C$54&$C3032 -> WY|exports|hydrogen

Sheet Calcs
A1: SECTION 1 - export share for every state and fuel (48 states x 21 fuels)
A2: The question this tab answers, one row per state and fuel: when demand for a fuel falls in this state, what share of that drop is made up by SHIPPING THE FUEL OUT of the state, rather than by producing less or bringing in less? A state that genuinely ships fuel out can absorb the drop that way; a state that only consumes, or that pipelines fuel straight through, cannot. Columns G-I are the state's 2025 fuel flows as the model itself holds them. Columns J-L build the share, column N is the answer that goes into the output file. Columns P-S re-run the same arithmetic on the raw published data instead, purely so the difference is visible - nothing downstream reads them. Columns T-W are checks: 1 means a problem, 0 means fine.
A3: State | B3: Fuel (name used in this file) | C3: Fuel (name used in the model's own data) | D3: US national share (the value every state carries today) | E3: How this row is filled rule = calculated / hold = keep the US value / zero = not a tradeable fuel | F3: Lookup key (state + fuel) | G3: Produced in the state 2025, BTU | H3: Brought in from outside 2025, BTU (imports) | I3: Shipped out of the state 2025, BTU (exports) | J3: Used inside the state produced + brought in - shipped out | K3: Genuinely available to redirect shipped out - brought in, never below zero | L3: What the share is measured against redirectable + used in state (equals production) | M3: Share the rule gives redirectable / the column to the left, capped at 100% | N3: EXPORT SHARE USED IN THE OUTPUT FILE the rule, or the US value for crude, or 0 | O3: Different from the US share? 1 = yes | P3: Produced in the state published data, 3-year average | Q3: Brought in from outside published data, 3-year average | R3: Shipped out of the state published data, 3-year average | S3: Share the rule would give on the published data instead | T3: CHECK: does the measuring base equal production? it must, wherever more is shipped out than brought in - 1 = problem | U3: CHECK: is the share between 0 and 100%? 1 = problem | V3: CHECK: is a non-fuel row accidentally non-zero? 1 = problem | W3: CHECK: did the 100% cap have to kick in? 1 = yes, which would need investigating | X3: Gap between the two shares how far the published data would move this row
A4: AL | B4: electricity (not used in this variable) | C4: =VLOOKUP($B4,Keys!$F$2:$I$22,2,FALSE) -> 0 | D4: =VLOOKUP($B4,Keys!$F$2:$I$22,3,FALSE) -> 0 | E4: =VLOOKUP($B4,Keys!$F$2:$I$22,4,FALSE) -> zero | F4: =$A4&Keys!$C$54&$B4 -> AL|electricity (not used in this variable) | G4: =IF($E4=Keys!$C$60,Keys!$C$51,INDEX(Balanced_2025!$D$9:$D$3032,MATCH($A4&Keys!$C$54&Keys!$C$55&Keys!$C$54&$C4,Balanced_2025!$E$9:$E$3032,0))) -> 0 | H4: =IF($E4=Keys!$C$60,Keys!$C$51,INDEX(Balanced_2025!$D$9:$D$3032,MATCH($A4&Keys!$C$54&Keys!$C$56&Keys!$C$54&$C4,Balanced_2025!$E$9:$E$3032,0))) -> 0 | I4: =IF($E4=Keys!$C$60,Keys!$C$51,INDEX(Balanced_2025!$D$9:$D$3032,MATCH($A4&Keys!$C$54&Keys!$C$57&Keys!$C$54&$C4,Balanced_2025!$E$9:$E$3032,0))) -> 0 | J4: =$G4+$H4-$I4 -> 0 | K4: =MAX(Keys!$C$51,$I4-$H4) -> 0 | L4: =$K4+$J4 -> 0 | M4: =IF($L4>Keys!$C$51,MIN(Keys!$C$52,$K4/$L4),Keys!$C$51) -> 0 | N4: =IF($E4=Keys!$C$60,Keys!$C$51,IF($E4=Keys!$C$59,$D4,$M4)) -> 0 | O4: =IF($N4<>$D4,1,0) -> 0 | P4: =IF($E4=Keys!$C$60,Keys!$C$51,INDEX(Raw_BFPIaE!$G$9:$G$3032,MATCH($A4&Keys!$C$54&Keys!$C$55&Keys!$C$54&$B4,Raw_BFPIaE!$H$9:$H$3032,0))) -> 0 | Q4: =IF($E4=Keys!$C$60,Keys!$C$51,INDEX(Raw_BFPIaE!$G$9:$G$3032,MATCH($A4&Keys!$C$54&Keys!$C$56&Keys!$C$54&$B4,Raw_BFPIaE!$H$9:$H$3032,0))) -> 0 | R4: =IF($E4=Keys!$C$60,Keys!$C$51,INDEX(Raw_BFPIaE!$G$9:$G$3032,MATCH($A4&Keys!$C$54&Keys!$C$57&Keys!$C$54&$B4,Raw_BFPIaE!$H$9:$H$3032,0))) -> 0 | S4: =IF(($P4+$Q4-$R4+MAX(Keys!$C$51,$R4-$Q4))>Keys!$C$51,MIN(Keys!$C$52,MAX(Keys!$C$51,$R4-$Q4)/($P4+$Q4-$R4+MAX(Keys!$C$51,$R4-$Q4))),Keys!$C$51) -> 0 | T4: =IF(AND($I4>$H4,ABS($L4-$G4)>MAX(Keys!$C$62,ABS($G4)*Keys!$C$63)),1,0) -> 0 | U4: =IF(OR($N4<Keys!$C$51,$N4>Keys!$C$52),1,0) -> 0 | V4: =IF(AND($E4=Keys!$C$60,$N4<>Keys!$C$51),1,0) -> 0 | W4: =IF($L4>Keys!$C$51,IF($K4/$L4>Keys!$C$52,1,0),0) -> 0 | X4: =ABS($M4-$S4) -> 0
A5: AL | B5: hard coal | C5: =VLOOKUP($B5,Keys!$F$2:$I$22,2,FALSE) -> hard coal | D5: =VLOOKUP($B5,Keys!$F$2:$I$22,3,FALSE) -> 0.13753988 | E5: =VLOOKUP($B5,Keys!$F$2:$I$22,4,FALSE) -> rule | F5: =$A5&Keys!$C$54&$B5 -> AL|hard coal | G5: =IF($E5=Keys!$C$60,Keys!$C$51,INDEX(Balanced_2025!$D$9:$D$3032,MATCH($A5&Keys!$C$54&Keys!$C$55&Keys!$C$54&$C5,Balanced_2025!$E$9:$E$3032,0))) -> 294838000000000 | H5: =IF($E5=Keys!$C$60,Keys!$C$51,INDEX(Balanced_2025!$D$9:$D$3032,MATCH($A5&Keys!$C$54&Keys!$C$56&Keys!$C$54&$C5,Balanced_2025!$E$9:$E$3032,0))) -> 75813100000000 | I5: =IF($E5=Keys!$C$60,Keys!$C$51,INDEX(Balanced_2025!$D$9:$D$3032,MATCH($A5&Keys!$C$54&Keys!$C$57&Keys!$C$54&$C5,Balanced_2025!$E$9:$E$3032,0))) -> 45989100000000 | J5: =$G5+$H5-$I5 -> 324662000000000 | K5: =MAX(Keys!$C$51,$I5-$H5) -> 0 | L5: =$K5+$J5 -> 324662000000000 | M5: =IF($L5>Keys!$C$51,MIN(Keys!$C$52,$K5/$L5),Keys!$C$51) -> 0 | N5: =IF($E5=Keys!$C$60,Keys!$C$51,IF($E5=Keys!$C$59,$D5,$M5)) -> 0 | O5: =IF($N5<>$D5,1,0) -> 1 | P5: =IF($E5=Keys!$C$60,Keys!$C$51,INDEX(Raw_BFPIaE!$G$9:$G$3032,MATCH($A5&Keys!$C$54&Keys!$C$55&Keys!$C$54&$B5,Raw_BFPIaE!$H$9:$H$3032,0))) -> 2.9484067e+14 | Q5: =IF($E5=Keys!$C$60,Keys!$C$51,INDEX(Raw_BFPIaE!$G$9:$G$3032,MATCH($A5&Keys!$C$54&Keys!$C$56&Keys!$C$54&$B5,Raw_BFPIaE!$H$9:$H$3032,0))) -> 7.8936433e+13 | R5: =IF($E5=Keys!$C$60,Keys!$C$51,INDEX(Raw_BFPIaE!$G$9:$G$3032,MATCH($A5&Keys!$C$54&Keys!$C$57&Keys!$C$54&$B5,Raw_BFPIaE!$H$9:$H$3032,0))) -> 15546880000000 | S5: =IF(($P5+$Q5-$R5+MAX(Keys!$C$51,$R5-$Q5))>Keys!$C$51,MIN(Keys!$C$52,MAX(Keys!$C$51,$R5-$Q5)/($P5+$Q5-$R5+MAX(Keys!$C$51,$R5-$Q5))),Keys!$C$51) -> 0 | T5: =IF(AND($I5>$H5,ABS($L5-$G5)>MAX(Keys!$C$62,ABS($G5)*Keys!$C$63)),1,0) -> 0 | U5: =IF(OR($N5<Keys!$C$51,$N5>Keys!$C$52),1,0) -> 0 | V5: =IF(AND($E5=Keys!$C$60,$N5<>Keys!$C$51),1,0) -> 0 | W5: =IF($L5>Keys!$C$51,IF($K5/$L5>Keys!$C$52,1,0),0) -> 0 | X5: =ABS($M5-$S5) -> 0
A6: AL | B6: natural gas | C6: =VLOOKUP($B6,Keys!$F$2:$I$22,2,FALSE) -> natural gas | D6: =VLOOKUP($B6,Keys!$F$2:$I$22,3,FALSE) -> 0.19083918 | E6: =VLOOKUP($B6,Keys!$F$2:$I$22,4,FALSE) -> rule | F6: =$A6&Keys!$C$54&$B6 -> AL|natural gas | G6: =IF($E6=Keys!$C$60,Keys!$C$51,INDEX(Balanced_2025!$D$9:$D$3032,MATCH($A6&Keys!$C$54&Keys!$C$55&Keys!$C$54&$C6,Balanced_2025!$E$9:$E$3032,0))) -> 76628100000000 | H6: =IF($E6=Keys!$C$60,Keys!$C$51,INDEX(Balanced_2025!$D$9:$D$3032,MATCH($A6&Keys!$C$54&Keys!$C$56&Keys!$C$54&$C6,Balanced_2025!$E$9:$E$3032,0))) -> 4.75849e+15 | I6: =IF($E6=Keys!$C$60,Keys!$C$51,INDEX(Balanced_2025!$D$9:$D$3032,MATCH($A6&Keys!$C$54&Keys!$C$57&Keys!$C$54&$C6,Balanced_2025!$E$9:$E$3032,0))) -> 4.11261e+15 | J6: =$G6+$H6-$I6 -> 722508100000000 | K6: =MAX(Keys!$C$51,$I6-$H6) -> 0 | L6: =$K6+$J6 -> 722508100000000 | M6: =IF($L6>Keys!$C$51,MIN(Keys!$C$52,$K6/$L6),Keys!$C$51) -> 0 | N6: =IF($E6=Keys!$C$60,Keys!$C$51,IF($E6=Keys!$C$59,$D6,$M6)) -> 0 | O6: =IF($N6<>$D6,1,0) -> 1 | P6: =IF($E6=Keys!$C$60,Keys!$C$51,INDEX(Raw_BFPIaE!$G$9:$G$3032,MATCH($A6&Keys!$C$54&Keys!$C$55&Keys!$C$54&$B6,Raw_BFPIaE!$H$9:$H$3032,0))) -> 7.6334833e+13 | Q6: =IF($E6=Keys!$C$60,Keys!$C$51,INDEX(Raw_BFPIaE!$G$9:$G$3032,MATCH($A6&Keys!$C$54&Keys!$C$56&Keys!$C$54&$B6,Raw_BFPIaE!$H$9:$H$3032,0))) -> 4.7814867e+15 | R6: =IF($E6=Keys!$C$60,Keys!$C$51,INDEX(Raw_BFPIaE!$G$9:$G$3032,MATCH($A6&Keys!$C$54&Keys!$C$57&Keys!$C$54&$B6,Raw_BFPIaE!$H$9:$H$3032,0))) -> 4.09687e+15 | S6: =IF(($P6+$Q6-$R6+MAX(Keys!$C$51,$R6-$Q6))>Keys!$C$51,MIN(Keys!$C$52,MAX(Keys!$C$51,$R6-$Q6)/($P6+$Q6-$R6+MAX(Keys!$C$51,$R6-$Q6))),Keys!$C$51) -> 0 | T6: =IF(AND($I6>$H6,ABS($L6-$G6)>MAX(Keys!$C$62,ABS($G6)*Keys!$C$63)),1,0) -> 0 | U6: =IF(OR($N6<Keys!$C$51,$N6>Keys!$C$52),1,0) -> 0 | V6: =IF(AND($E6=Keys!$C$60,$N6<>Keys!$C$51),1,0) -> 0 | W6: =IF($L6>Keys!$C$51,IF($K6/$L6>Keys!$C$52,1,0),0) -> 0 | X6: =ABS($M6-$S6) -> 0
A7: AL | B7: nuclear | C7: =VLOOKUP($B7,Keys!$F$2:$I$22,2,FALSE) -> 0 | D7: =VLOOKUP($B7,Keys!$F$2:$I$22,3,FALSE) -> 0 | E7: =VLOOKUP($B7,Keys!$F$2:$I$22,4,FALSE) -> zero | F7: =$A7&Keys!$C$54&$B7 -> AL|nuclear | G7: =IF($E7=Keys!$C$60,Keys!$C$51,INDEX(Balanced_2025!$D$9:$D$3032,MATCH($A7&Keys!$C$54&Keys!$C$55&Keys!$C$54&$C7,Balanced_2025!$E$9:$E$3032,0))) -> 0 | H7: =IF($E7=Keys!$C$60,Keys!$C$51,INDEX(Balanced_2025!$D$9:$D$3032,MATCH($A7&Keys!$C$54&Keys!$C$56&Keys!$C$54&$C7,Balanced_2025!$E$9:$E$3032,0))) -> 0 | I7: =IF($E7=Keys!$C$60,Keys!$C$51,INDEX(Balanced_2025!$D$9:$D$3032,MATCH($A7&Keys!$C$54&Keys!$C$57&Keys!$C$54&$C7,Balanced_2025!$E$9:$E$3032,0))) -> 0 | J7: =$G7+$H7-$I7 -> 0 | K7: =MAX(Keys!$C$51,$I7-$H7) -> 0 | L7: =$K7+$J7 -> 0 | M7: =IF($L7>Keys!$C$51,MIN(Keys!$C$52,$K7/$L7),Keys!$C$51) -> 0 | N7: =IF($E7=Keys!$C$60,Keys!$C$51,IF($E7=Keys!$C$59,$D7,$M7)) -> 0 | O7: =IF($N7<>$D7,1,0) -> 0 | P7: =IF($E7=Keys!$C$60,Keys!$C$51,INDEX(Raw_BFPIaE!$G$9:$G$3032,MATCH($A7&Keys!$C$54&Keys!$C$55&Keys!$C$54&$B7,Raw_BFPIaE!$H$9:$H$3032,0))) -> 0 | Q7: =IF($E7=Keys!$C$60,Keys!$C$51,INDEX(Raw_BFPIaE!$G$9:$G$3032,MATCH($A7&Keys!$C$54&Keys!$C$56&Keys!$C$54&$B7,Raw_BFPIaE!$H$9:$H$3032,0))) -> 0 | R7: =IF($E7=Keys!$C$60,Keys!$C$51,INDEX(Raw_BFPIaE!$G$9:$G$3032,MATCH($A7&Keys!$C$54&Keys!$C$57&Keys!$C$54&$B7,Raw_BFPIaE!$H$9:$H$3032,0))) -> 0 | S7: =IF(($P7+$Q7-$R7+MAX(Keys!$C$51,$R7-$Q7))>Keys!$C$51,MIN(Keys!$C$52,MAX(Keys!$C$51,$R7-$Q7)/($P7+$Q7-$R7+MAX(Keys!$C$51,$R7-$Q7))),Keys!$C$51) -> 0 | T7: =IF(AND($I7>$H7,ABS($L7-$G7)>MAX(Keys!$C$62,ABS($G7)*Keys!$C$63)),1,0) -> 0 | U7: =IF(OR($N7<Keys!$C$51,$N7>Keys!$C$52),1,0) -> 0 | V7: =IF(AND($E7=Keys!$C$60,$N7<>Keys!$C$51),1,0) -> 0 | W7: =IF($L7>Keys!$C$51,IF($K7/$L7>Keys!$C$52,1,0),0) -> 0 | X7: =ABS($M7-$S7) -> 0
A8: AL | B8: hydro (is not a fuel) | C8: =VLOOKUP($B8,Keys!$F$2:$I$22,2,FALSE) -> 0 | D8: =VLOOKUP($B8,Keys!$F$2:$I$22,3,FALSE) -> 0 | E8: =VLOOKUP($B8,Keys!$F$2:$I$22,4,FALSE) -> zero | F8: =$A8&Keys!$C$54&$B8 -> AL|hydro (is not a fuel) | G8: =IF($E8=Keys!$C$60,Keys!$C$51,INDEX(Balanced_2025!$D$9:$D$3032,MATCH($A8&Keys!$C$54&Keys!$C$55&Keys!$C$54&$C8,Balanced_2025!$E$9:$E$3032,0))) -> 0 | H8: =IF($E8=Keys!$C$60,Keys!$C$51,INDEX(Balanced_2025!$D$9:$D$3032,MATCH($A8&Keys!$C$54&Keys!$C$56&Keys!$C$54&$C8,Balanced_2025!$E$9:$E$3032,0))) -> 0 | I8: =IF($E8=Keys!$C$60,Keys!$C$51,INDEX(Balanced_2025!$D$9:$D$3032,MATCH($A8&Keys!$C$54&Keys!$C$57&Keys!$C$54&$C8,Balanced_2025!$E$9:$E$3032,0))) -> 0 | J8: =$G8+$H8-$I8 -> 0 | K8: =MAX(Keys!$C$51,$I8-$H8) -> 0 | L8: =$K8+$J8 -> 0 | M8: =IF($L8>Keys!$C$51,MIN(Keys!$C$52,$K8/$L8),Keys!$C$51) -> 0 | N8: =IF($E8=Keys!$C$60,Keys!$C$51,IF($E8=Keys!$C$59,$D8,$M8)) -> 0 | O8: =IF($N8<>$D8,1,0) -> 0 | P8: =IF($E8=Keys!$C$60,Keys!$C$51,INDEX(Raw_BFPIaE!$G$9:$G$3032,MATCH($A8&Keys!$C$54&Keys!$C$55&Keys!$C$54&$B8,Raw_BFPIaE!$H$9:$H$3032,0))) -> 0 | Q8: =IF($E8=Keys!$C$60,Keys!$C$51,INDEX(Raw_BFPIaE!$G$9:$G$3032,MATCH($A8&Keys!$C$54&Keys!$C$56&Keys!$C$54&$B8,Raw_BFPIaE!$H$9:$H$3032,0))) -> 0 | R8: =IF($E8=Keys!$C$60,Keys!$C$51,INDEX(Raw_BFPIaE!$G$9:$G$3032,MATCH($A8&Keys!$C$54&Keys!$C$57&Keys!$C$54&$B8,Raw_BFPIaE!$H$9:$H$3032,0))) -> 0 | S8: =IF(($P8+$Q8-$R8+MAX(Keys!$C$51,$R8-$Q8))>Keys!$C$51,MIN(Keys!$C$52,MAX(Keys!$C$51,$R8-$Q8)/($P8+$Q8-$R8+MAX(Keys!$C$51,$R8-$Q8))),Keys!$C$51) -> 0 | T8: =IF(AND($I8>$H8,ABS($L8-$G8)>MAX(Keys!$C$62,ABS($G8)*Keys!$C$63)),1,0) -> 0 | U8: =IF(OR($N8<Keys!$C$51,$N8>Keys!$C$52),1,0) -> 0 | V8: =IF(AND($E8=Keys!$C$60,$N8<>Keys!$C$51),1,0) -> 0 | W8: =IF($L8>Keys!$C$51,IF($K8/$L8>Keys!$C$52,1,0),0) -> 0 | X8: =ABS($M8-$S8) -> 0
A9: AL | B9: wind (is not a fuel) | C9: =VLOOKUP($B9,Keys!$F$2:$I$22,2,FALSE) -> 0 | D9: =VLOOKUP($B9,Keys!$F$2:$I$22,3,FALSE) -> 0 | E9: =VLOOKUP($B9,Keys!$F$2:$I$22,4,FALSE) -> zero | F9: =$A9&Keys!$C$54&$B9 -> AL|wind (is not a fuel) | G9: =IF($E9=Keys!$C$60,Keys!$C$51,INDEX(Balanced_2025!$D$9:$D$3032,MATCH($A9&Keys!$C$54&Keys!$C$55&Keys!$C$54&$C9,Balanced_2025!$E$9:$E$3032,0))) -> 0 | H9: =IF($E9=Keys!$C$60,Keys!$C$51,INDEX(Balanced_2025!$D$9:$D$3032,MATCH($A9&Keys!$C$54&Keys!$C$56&Keys!$C$54&$C9,Balanced_2025!$E$9:$E$3032,0))) -> 0 | I9: =IF($E9=Keys!$C$60,Keys!$C$51,INDEX(Balanced_2025!$D$9:$D$3032,MATCH($A9&Keys!$C$54&Keys!$C$57&Keys!$C$54&$C9,Balanced_2025!$E$9:$E$3032,0))) -> 0 | J9: =$G9+$H9-$I9 -> 0 | K9: =MAX(Keys!$C$51,$I9-$H9) -> 0 | L9: =$K9+$J9 -> 0 | M9: =IF($L9>Keys!$C$51,MIN(Keys!$C$52,$K9/$L9),Keys!$C$51) -> 0 | N9: =IF($E9=Keys!$C$60,Keys!$C$51,IF($E9=Keys!$C$59,$D9,$M9)) -> 0 | O9: =IF($N9<>$D9,1,0) -> 0 | P9: =IF($E9=Keys!$C$60,Keys!$C$51,INDEX(Raw_BFPIaE!$G$9:$G$3032,MATCH($A9&Keys!$C$54&Keys!$C$55&Keys!$C$54&$B9,Raw_BFPIaE!$H$9:$H$3032,0))) -> 0 | Q9: =IF($E9=Keys!$C$60,Keys!$C$51,INDEX(Raw_BFPIaE!$G$9:$G$3032,MATCH($A9&Keys!$C$54&Keys!$C$56&Keys!$C$54&$B9,Raw_BFPIaE!$H$9:$H$3032,0))) -> 0 | R9: =IF($E9=Keys!$C$60,Keys!$C$51,INDEX(Raw_BFPIaE!$G$9:$G$3032,MATCH($A9&Keys!$C$54&Keys!$C$57&Keys!$C$54&$B9,Raw_BFPIaE!$H$9:$H$3032,0))) -> 0 | S9: =IF(($P9+$Q9-$R9+MAX(Keys!$C$51,$R9-$Q9))>Keys!$C$51,MIN(Keys!$C$52,MAX(Keys!$C$51,$R9-$Q9)/($P9+$Q9-$R9+MAX(Keys!$C$51,$R9-$Q9))),Keys!$C$51) -> 0 | T9: =IF(AND($I9>$H9,ABS($L9-$G9)>MAX(Keys!$C$62,ABS($G9)*Keys!$C$63)),1,0) -> 0 | U9: =IF(OR($N9<Keys!$C$51,$N9>Keys!$C$52),1,0) -> 0 | V9: =IF(AND($E9=Keys!$C$60,$N9<>Keys!$C$51),1,0) -> 0 | W9: =IF($L9>Keys!$C$51,IF($K9/$L9>Keys!$C$52,1,0),0) -> 0 | X9: =ABS($M9-$S9) -> 0
A10: AL | B10: solar (is not a fuel) | C10: =VLOOKUP($B10,Keys!$F$2:$I$22,2,FALSE) -> 0 | D10: =VLOOKUP($B10,Keys!$F$2:$I$22,3,FALSE) -> 0 | E10: =VLOOKUP($B10,Keys!$F$2:$I$22,4,FALSE) -> zero | F10: =$A10&Keys!$C$54&$B10 -> AL|solar (is not a fuel) | G10: =IF($E10=Keys!$C$60,Keys!$C$51,INDEX(Balanced_2025!$D$9:$D$3032,MATCH($A10&Keys!$C$54&Keys!$C$55&Keys!$C$54&$C10,Balanced_2025!$E$9:$E$3032,0))) -> 0 | H10: =IF($E10=Keys!$C$60,Keys!$C$51,INDEX(Balanced_2025!$D$9:$D$3032,MATCH($A10&Keys!$C$54&Keys!$C$56&Keys!$C$54&$C10,Balanced_2025!$E$9:$E$3032,0))) -> 0 | I10: =IF($E10=Keys!$C$60,Keys!$C$51,INDEX(Balanced_2025!$D$9:$D$3032,MATCH($A10&Keys!$C$54&Keys!$C$57&Keys!$C$54&$C10,Balanced_2025!$E$9:$E$3032,0))) -> 0 | J10: =$G10+$H10-$I10 -> 0 | K10: =MAX(Keys!$C$51,$I10-$H10) -> 0 | L10: =$K10+$J10 -> 0 | M10: =IF($L10>Keys!$C$51,MIN(Keys!$C$52,$K10/$L10),Keys!$C$51) -> 0 | N10: =IF($E10=Keys!$C$60,Keys!$C$51,IF($E10=Keys!$C$59,$D10,$M10)) -> 0 | O10: =IF($N10<>$D10,1,0) -> 0 | P10: =IF($E10=Keys!$C$60,Keys!$C$51,INDEX(Raw_BFPIaE!$G$9:$G$3032,MATCH($A10&Keys!$C$54&Keys!$C$55&Keys!$C$54&$B10,Raw_BFPIaE!$H$9:$H$3032,0))) -> 0 | Q10: =IF($E10=Keys!$C$60,Keys!$C$51,INDEX(Raw_BFPIaE!$G$9:$G$3032,MATCH($A10&Keys!$C$54&Keys!$C$56&Keys!$C$54&$B10,Raw_BFPIaE!$H$9:$H$3032,0))) -> 0 | R10: =IF($E10=Keys!$C$60,Keys!$C$51,INDEX(Raw_BFPIaE!$G$9:$G$3032,MATCH($A10&Keys!$C$54&Keys!$C$57&Keys!$C$54&$B10,Raw_BFPIaE!$H$9:$H$3032,0))) -> 0 | S10: =IF(($P10+$Q10-$R10+MAX(Keys!$C$51,$R10-$Q10))>Keys!$C$51,MIN(Keys!$C$52,MAX(Keys!$C$51,$R10-$Q10)/($P10+$Q10-$R10+MAX(Keys!$C$51,$R10-$Q10))),Keys!$C$51) -> 0 | T10: =IF(AND($I10>$H10,ABS($L10-$G10)>MAX(Keys!$C$62,ABS($G10)*Keys!$C$63)),1,0) -> 0 | U10: =IF(OR($N10<Keys!$C$51,$N10>Keys!$C$52),1,0) -> 0 | V10: =IF(AND($E10=Keys!$C$60,$N10<>Keys!$C$51),1,0) -> 0 | W10: =IF($L10>Keys!$C$51,IF($K10/$L10>Keys!$C$52,1,0),0) -> 0 | X10: =ABS($M10-$S10) -> 0
A11: AL | B11: biomass | C11: =VLOOKUP($B11,Keys!$F$2:$I$22,2,FALSE) -> biomass | D11: =VLOOKUP($B11,Keys!$F$2:$I$22,3,FALSE) -> 0.74947425 | E11: =VLOOKUP($B11,Keys!$F$2:$I$22,4,FALSE) -> rule | F11: =$A11&Keys!$C$54&$B11 -> AL|biomass | G11: =IF($E11=Keys!$C$60,Keys!$C$51,INDEX(Balanced_2025!$D$9:$D$3032,MATCH($A11&Keys!$C$54&Keys!$C$55&Keys!$C$54&$C11,Balanced_2025!$E$9:$E$3032,0))) -> 13897400000000 | H11: =IF($E11=Keys!$C$60,Keys!$C$51,INDEX(Balanced_2025!$D$9:$D$3032,MATCH($A11&Keys!$C$54&Keys!$C$56&Keys!$C$54&$C11,Balanced_2025!$E$9:$E$3032,0))) -> 158106000000000 | I11: =IF($E11=Keys!$C$60,Keys!$C$51,INDEX(Balanced_2025!$D$9:$D$3032,MATCH($A11&Keys!$C$54&Keys!$C$57&Keys!$C$54&$C11,Balanced_2025!$E$9:$E$3032,0))) -> 0 | J11: =$G11+$H11-$I11 -> 172003400000000 | K11: =MAX(Keys!$C$51,$I11-$H11) -> 0 | L11: =$K11+$J11 -> 172003400000000 | M11: =IF($L11>Keys!$C$51,MIN(Keys!$C$52,$K11/$L11),Keys!$C$51) -> 0 | N11: =IF($E11=Keys!$C$60,Keys!$C$51,IF($E11=Keys!$C$59,$D11,$M11)) -> 0 | O11: =IF($N11<>$D11,1,0) -> 1 | P11: =IF($E11=Keys!$C$60,Keys!$C$51,INDEX(Raw_BFPIaE!$G$9:$G$3032,MATCH($A11&Keys!$C$54&Keys!$C$55&Keys!$C$54&$B11,Raw_BFPIaE!$H$9:$H$3032,0))) -> 13897400000000 | Q11: =IF($E11=Keys!$C$60,Keys!$C$51,INDEX(Raw_BFPIaE!$G$9:$G$3032,MATCH($A11&Keys!$C$54&Keys!$C$56&Keys!$C$54&$B11,Raw_BFPIaE!$H$9:$H$3032,0))) -> 1.0841133e+14 | R11: =IF($E11=Keys!$C$60,Keys!$C$51,INDEX(Raw_BFPIaE!$G$9:$G$3032,MATCH($A11&Keys!$C$54&Keys!$C$57&Keys!$C$54&$B11,Raw_BFPIaE!$H$9:$H$3032,0))) -> 0 | S11: =IF(($P11+$Q11-$R11+MAX(Keys!$C$51,$R11-$Q11))>Keys!$C$51,MIN(Keys!$C$52,MAX(Keys!$C$51,$R11-$Q11)/($P11+$Q11-$R11+MAX(Keys!$C$51,$R11-$Q11))),Keys!$C$51) -> 0 | T11: =IF(AND($I11>$H11,ABS($L11-$G11)>MAX(Keys!$C$62,ABS($G11)*Keys!$C$63)),1,0) -> 0 | U11: =IF(OR($N11<Keys!$C$51,$N11>Keys!$C$52),1,0) -> 0 | V11: =IF(AND($E11=Keys!$C$60,$N11<>Keys!$C$51),1,0) -> 0 | W11: =IF($L11>Keys!$C$51,IF($K11/$L11>Keys!$C$52,1,0),0) -> 0 | X11: =ABS($M11-$S11) -> 0
A12: AL | B12: petroleum gasoline | C12: =VLOOKUP($B12,Keys!$F$2:$I$22,2,FALSE) -> petroleum gasoline | D12: =VLOOKUP($B12,Keys!$F$2:$I$22,3,FALSE) -> 0.075004052 | E12: =VLOOKUP($B12,Keys!$F$2:$I$22,4,FALSE) -> rule | F12: =$A12&Keys!$C$54&$B12 -> AL|petroleum gasoline | G12: =IF($E12=Keys!$C$60,Keys!$C$51,INDEX(Balanced_2025!$D$9:$D$3032,MATCH($A12&Keys!$C$54&Keys!$C$55&Keys!$C$54&$C12,Balanced_2025!$E$9:$E$3032,0))) -> 137908000000000 | H12: =IF($E12=Keys!$C$60,Keys!$C$51,INDEX(Balanced_2025!$D$9:$D$3032,MATCH($A12&Keys!$C$54&Keys!$C$56&Keys!$C$54&$C12,Balanced_2025!$E$9:$E$3032,0))) -> 216640000000000 | I12: =IF($E12=Keys!$C$60,Keys!$C$51,INDEX(Balanced_2025!$D$9:$D$3032,MATCH($A12&Keys!$C$54&Keys!$C$57&Keys!$C$54&$C12,Balanced_2025!$E$9:$E$3032,0))) -> 0 | J12: =$G12+$H12-$I12 -> 354548000000000 | K12: =MAX(Keys!$C$51,$I12-$H12) -> 0 | L12: =$K12+$J12 -> 354548000000000 | M12: =IF($L12>Keys!$C$51,MIN(Keys!$C$52,$K12/$L12),Keys!$C$51) -> 0 | N12: =IF($E12=Keys!$C$60,Keys!$C$51,IF($E12=Keys!$C$59,$D12,$M12)) -> 0 | O12: =IF($N12<>$D12,1,0) -> 1 | P12: =IF($E12=Keys!$C$60,Keys!$C$51,INDEX(Raw_BFPIaE!$G$9:$G$3032,MATCH($A12&Keys!$C$54&Keys!$C$55&Keys!$C$54&$B12,Raw_BFPIaE!$H$9:$H$3032,0))) -> 1.3679367e+14 | Q12: =IF($E12=Keys!$C$60,Keys!$C$51,INDEX(Raw_BFPIaE!$G$9:$G$3032,MATCH($A12&Keys!$C$54&Keys!$C$56&Keys!$C$54&$B12,Raw_BFPIaE!$H$9:$H$3032,0))) -> 1.3129833e+14 | R12: =IF($E12=Keys!$C$60,Keys!$C$51,INDEX(Raw_BFPIaE!$G$9:$G$3032,MATCH($A12&Keys!$C$54&Keys!$C$57&Keys!$C$54&$B12,Raw_BFPIaE!$H$9:$H$3032,0))) -> 0 | S12: =IF(($P12+$Q12-$R12+MAX(Keys!$C$51,$R12-$Q12))>Keys!$C$51,MIN(Keys!$C$52,MAX(Keys!$C$51,$R12-$Q12)/($P12+$Q12-$R12+MAX(Keys!$C$51,$R12-$Q12))),Keys!$C$51) -> 0 | T12: =IF(AND($I12>$H12,ABS($L12-$G12)>MAX(Keys!$C$62,ABS($G12)*Keys!$C$63)),1,0) -> 0 | U12: =IF(OR($N12<Keys!$C$51,$N12>Keys!$C$52),1,0) -> 0 | V12: =IF(AND($E12=Keys!$C$60,$N12<>Keys!$C$51),1,0) -> 0 | W12: =IF($L12>Keys!$C$51,IF($K12/$L12>Keys!$C$52,1,0),0) -> 0 | X12: =ABS($M12-$S12) -> 0
A13: AL | B13: petroleum diesel | C13: =VLOOKUP($B13,Keys!$F$2:$I$22,2,FALSE) -> petroleum diesel | D13: =VLOOKUP($B13,Keys!$F$2:$I$22,3,FALSE) -> 0.26691052 | E13: =VLOOKUP($B13,Keys!$F$2:$I$22,4,FALSE) -> rule | F13: =$A13&Keys!$C$54&$B13 -> AL|petroleum diesel | G13: =IF($E13=Keys!$C$60,Keys!$C$51,INDEX(Balanced_2025!$D$9:$D$3032,MATCH($A13&Keys!$C$54&Keys!$C$55&Keys!$C$54&$C13,Balanced_2025!$E$9:$E$3032,0))) -> 81574700000000 | H13: =IF($E13=Keys!$C$60,Keys!$C$51,INDEX(Balanced_2025!$D$9:$D$3032,MATCH($A13&Keys!$C$54&Keys!$C$56&Keys!$C$54&$C13,Balanced_2025!$E$9:$E$3032,0))) -> 99160900000000 | I13: =IF($E13=Keys!$C$60,Keys!$C$51,INDEX(Balanced_2025!$D$9:$D$3032,MATCH($A13&Keys!$C$54&Keys!$C$57&Keys!$C$54&$C13,Balanced_2025!$E$9:$E$3032,0))) -> 17761500000000 | J13: =$G13+$H13-$I13 -> 162974100000000 | K13: =MAX(Keys!$C$51,$I13-$H13) -> 0 | L13: =$K13+$J13 -> 162974100000000 | M13: =IF($L13>Keys!$C$51,MIN(Keys!$C$52,$K13/$L13),Keys!$C$51) -> 0 | N13: =IF($E13=Keys!$C$60,Keys!$C$51,IF($E13=Keys!$C$59,$D13,$M13)) -> 0 | O13: =IF($N13<>$D13,1,0) -> 1 | P13: =IF($E13=Keys!$C$60,Keys!$C$51,INDEX(Raw_BFPIaE!$G$9:$G$3032,MATCH($A13&Keys!$C$54&Keys!$C$55&Keys!$C$54&$B13,Raw_BFPIaE!$H$9:$H$3032,0))) -> 8.0915633e+13 | Q13: =IF($E13=Keys!$C$60,Keys!$C$51,INDEX(Raw_BFPIaE!$G$9:$G$3032,MATCH($A13&Keys!$C$54&Keys!$C$56&Keys!$C$54&$B13,Raw_BFPIaE!$H$9:$H$3032,0))) -> 64915300000000 | R13: =IF($E13=Keys!$C$60,Keys!$C$51,INDEX(Raw_BFPIaE!$G$9:$G$3032,MATCH($A13&Keys!$C$54&Keys!$C$57&Keys!$C$54&$B13,Raw_BFPIaE!$H$9:$H$3032,0))) -> 17618000000000 | S13: =IF(($P13+$Q13-$R13+MAX(Keys!$C$51,$R13-$Q13))>Keys!$C$51,MIN(Keys!$C$52,MAX(Keys!$C$51,$R13-$Q13)/($P13+$Q13-$R13+MAX(Keys!$C$51,$R13-$Q13))),Keys!$C$51) -> 0 | T13: =IF(AND($I13>$H13,ABS($L13-$G13)>MAX(Keys!$C$62,ABS($G13)*Keys!$C$63)),1,0) -> 0 | U13: =IF(OR($N13<Keys!$C$51,$N13>Keys!$C$52),1,0) -> 0 | V13: =IF(AND($E13=Keys!$C$60,$N13<>Keys!$C$51),1,0) -> 0 | W13: =IF($L13>Keys!$C$51,IF($K13/$L13>Keys!$C$52,1,0),0) -> 0 | X13: =ABS($M13-$S13) -> 0
A14: AL | B14: biofuel gasoline | C14: =VLOOKUP($B14,Keys!$F$2:$I$22,2,FALSE) -> biofuel gasoline | D14: =VLOOKUP($B14,Keys!$F$2:$I$22,3,FALSE) -> 0.087213884 | E14: =VLOOKUP($B14,Keys!$F$2:$I$22,4,FALSE) -> rule | F14: =$A14&Keys!$C$54&$B14 -> AL|biofuel gasoline | G14: =IF($E14=Keys!$C$60,Keys!$C$51,INDEX(Balanced_2025!$D$9:$D$3032,MATCH($A14&Keys!$C$54&Keys!$C$55&Keys!$C$54&$C14,Balanced_2025!$E$9:$E$3032,0))) -> 0 | H14: =IF($E14=Keys!$C$60,Keys!$C$51,INDEX(Balanced_2025!$D$9:$D$3032,MATCH($A14&Keys!$C$54&Keys!$C$56&Keys!$C$54&$C14,Balanced_2025!$E$9:$E$3032,0))) -> 25214800000000 | I14: =IF($E14=Keys!$C$60,Keys!$C$51,INDEX(Balanced_2025!$D$9:$D$3032,MATCH($A14&Keys!$C$54&Keys!$C$57&Keys!$C$54&$C14,Balanced_2025!$E$9:$E$3032,0))) -> 0 | J14: =$G14+$H14-$I14 -> 25214800000000 | K14: =MAX(Keys!$C$51,$I14-$H14) -> 0 | L14: =$K14+$J14 -> 25214800000000 | M14: =IF($L14>Keys!$C$51,MIN(Keys!$C$52,$K14/$L14),Keys!$C$51) -> 0 | N14: =IF($E14=Keys!$C$60,Keys!$C$51,IF($E14=Keys!$C$59,$D14,$M14)) -> 0 | O14: =IF($N14<>$D14,1,0) -> 1 | P14: =IF($E14=Keys!$C$60,Keys!$C$51,INDEX(Raw_BFPIaE!$G$9:$G$3032,MATCH($A14&Keys!$C$54&Keys!$C$55&Keys!$C$54&$B14,Raw_BFPIaE!$H$9:$H$3032,0))) -> 0 | Q14: =IF($E14=Keys!$C$60,Keys!$C$51,INDEX(Raw_BFPIaE!$G$9:$G$3032,MATCH($A14&Keys!$C$54&Keys!$C$56&Keys!$C$54&$B14,Raw_BFPIaE!$H$9:$H$3032,0))) -> 1.5789033e+13 | R14: =IF($E14=Keys!$C$60,Keys!$C$51,INDEX(Raw_BFPIaE!$G$9:$G$3032,MATCH($A14&Keys!$C$54&Keys!$C$57&Keys!$C$54&$B14,Raw_BFPIaE!$H$9:$H$3032,0))) -> 0 | S14: =IF(($P14+$Q14-$R14+MAX(Keys!$C$51,$R14-$Q14))>Keys!$C$51,MIN(Keys!$C$52,MAX(Keys!$C$51,$R14-$Q14)/($P14+$Q14-$R14+MAX(Keys!$C$51,$R14-$Q14))),Keys!$C$51) -> 0 | T14: =IF(AND($I14>$H14,ABS($L14-$G14)>MAX(Keys!$C$62,ABS($G14)*Keys!$C$63)),1,0) -> 0 | U14: =IF(OR($N14<Keys!$C$51,$N14>Keys!$C$52),1,0) -> 0 | V14: =IF(AND($E14=Keys!$C$60,$N14<>Keys!$C$51),1,0) -> 0 | W14: =IF($L14>Keys!$C$51,IF($K14/$L14>Keys!$C$52,1,0),0) -> 0 | X14: =ABS($M14-$S14) -> 0
A15: AL | B15: biofuel diesel | C15: =VLOOKUP($B15,Keys!$F$2:$I$22,2,FALSE) -> biofuel diesel | D15: =VLOOKUP($B15,Keys!$F$2:$I$22,3,FALSE) -> 0.058642381 | E15: =VLOOKUP($B15,Keys!$F$2:$I$22,4,FALSE) -> rule | F15: =$A15&Keys!$C$54&$B15 -> AL|biofuel diesel | G15: =IF($E15=Keys!$C$60,Keys!$C$51,INDEX(Balanced_2025!$D$9:$D$3032,MATCH($A15&Keys!$C$54&Keys!$C$55&Keys!$C$54&$C15,Balanced_2025!$E$9:$E$3032,0))) -> 6007590000000 | H15: =IF($E15=Keys!$C$60,Keys!$C$51,INDEX(Balanced_2025!$D$9:$D$3032,MATCH($A15&Keys!$C$54&Keys!$C$56&Keys!$C$54&$C15,Balanced_2025!$E$9:$E$3032,0))) -> 83777100000 | I15: =IF($E15=Keys!$C$60,Keys!$C$51,INDEX(Balanced_2025!$D$9:$D$3032,MATCH($A15&Keys!$C$54&Keys!$C$57&Keys!$C$54&$C15,Balanced_2025!$E$9:$E$3032,0))) -> 3014380000000 | J15: =$G15+$H15-$I15 -> 3076987100000 | K15: =MAX(Keys!$C$51,$I15-$H15) -> 2930602900000 | L15: =$K15+$J15 -> 6007590000000 | M15: =IF($L15>Keys!$C$51,MIN(Keys!$C$52,$K15/$L15),Keys!$C$51) -> 0.48781673 | N15: =IF($E15=Keys!$C$60,Keys!$C$51,IF($E15=Keys!$C$59,$D15,$M15)) -> 0.48781673 | O15: =IF($N15<>$D15,1,0) -> 1 | P15: =IF($E15=Keys!$C$60,Keys!$C$51,INDEX(Raw_BFPIaE!$G$9:$G$3032,MATCH($A15&Keys!$C$54&Keys!$C$55&Keys!$C$54&$B15,Raw_BFPIaE!$H$9:$H$3032,0))) -> 6383790000000 | Q15: =IF($E15=Keys!$C$60,Keys!$C$51,INDEX(Raw_BFPIaE!$G$9:$G$3032,MATCH($A15&Keys!$C$54&Keys!$C$56&Keys!$C$54&$B15,Raw_BFPIaE!$H$9:$H$3032,0))) -> 0 | R15: =IF($E15=Keys!$C$60,Keys!$C$51,INDEX(Raw_BFPIaE!$G$9:$G$3032,MATCH($A15&Keys!$C$54&Keys!$C$57&Keys!$C$54&$B15,Raw_BFPIaE!$H$9:$H$3032,0))) -> 2380440000000 | S15: =IF(($P15+$Q15-$R15+MAX(Keys!$C$51,$R15-$Q15))>Keys!$C$51,MIN(Keys!$C$52,MAX(Keys!$C$51,$R15-$Q15)/($P15+$Q15-$R15+MAX(Keys!$C$51,$R15-$Q15))),Keys!$C$51) -> 0.37288821 | T15: =IF(AND($I15>$H15,ABS($L15-$G15)>MAX(Keys!$C$62,ABS($G15)*Keys!$C$63)),1,0) -> 0 | U15: =IF(OR($N15<Keys!$C$51,$N15>Keys!$C$52),1,0) -> 0 | V15: =IF(AND($E15=Keys!$C$60,$N15<>Keys!$C$51),1,0) -> 0 | W15: =IF($L15>Keys!$C$51,IF($K15/$L15>Keys!$C$52,1,0),0) -> 0 | X15: =ABS($M15-$S15) -> 0.11492852
... A1011: WY | B1011: hydrogen | C1011: =VLOOKUP($B1011,Keys!$F$2:$I$22,2,FALSE) -> 0 | D1011: =VLOOKUP($B1011,Keys!$F$2:$I$22,3,FALSE) -> 0 | E1011: =VLOOKUP($B1011,Keys!$F$2:$I$22,4,FALSE) -> zero | F1011: =$A1011&Keys!$C$54&$B1011 -> WY|hydrogen | G1011: =IF($E1011=Keys!$C$60,Keys!$C$51,INDEX(Balanced_2025!$D$9:$D$3032,MATCH($A1011&Keys!$C$54&Keys!$C$55&Keys!$C$54&$C1011,Balanced_2025!$E$9:$E$3032,0))) -> 0 | H1011: =IF($E1011=Keys!$C$60,Keys!$C$51,INDEX(Balanced_2025!$D$9:$D$3032,MATCH($A1011&Keys!$C$54&Keys!$C$56&Keys!$C$54&$C1011,Balanced_2025!$E$9:$E$3032,0))) -> 0 | I1011: =IF($E1011=Keys!$C$60,Keys!$C$51,INDEX(Balanced_2025!$D$9:$D$3032,MATCH($A1011&Keys!$C$54&Keys!$C$57&Keys!$C$54&$C1011,Balanced_2025!$E$9:$E$3032,0))) -> 0 | J1011: =$G1011+$H1011-$I1011 -> 0 | K1011: =MAX(Keys!$C$51,$I1011-$H1011) -> 0 | L1011: =$K1011+$J1011 -> 0 | M1011: =IF($L1011>Keys!$C$51,MIN(Keys!$C$52,$K1011/$L1011),Keys!$C$51) -> 0 | N1011: =IF($E1011=Keys!$C$60,Keys!$C$51,IF($E1011=Keys!$C$59,$D1011,$M1011)) -> 0 | O1011: =IF($N1011<>$D1011,1,0) -> 0 | P1011: =IF($E1011=Keys!$C$60,Keys!$C$51,INDEX(Raw_BFPIaE!$G$9:$G$3032,MATCH($A1011&Keys!$C$54&Keys!$C$55&Keys!$C$54&$B1011,Raw_BFPIaE!$H$9:$H$3032,0))) -> 0 | Q1011: =IF($E1011=Keys!$C$60,Keys!$C$51,INDEX(Raw_BFPIaE!$G$9:$G$3032,MATCH($A1011&Keys!$C$54&Keys!$C$56&Keys!$C$54&$B1011,Raw_BFPIaE!$H$9:$H$3032,0))) -> 0 | R1011: =IF($E1011=Keys!$C$60,Keys!$C$51,INDEX(Raw_BFPIaE!$G$9:$G$3032,MATCH($A1011&Keys!$C$54&Keys!$C$57&Keys!$C$54&$B1011,Raw_BFPIaE!$H$9:$H$3032,0))) -> 0 | S1011: =IF(($P1011+$Q1011-$R1011+MAX(Keys!$C$51,$R1011-$Q1011))>Keys!$C$51,MIN(Keys!$C$52,MAX(Keys!$C$51,$R1011-$Q1011)/($P1011+$Q1011-$R1011+MAX(Keys!$C$51,$R1011-$Q1011))),Keys!$C$51) -> 0 | T1011: =IF(AND($I1011>$H1011,ABS($L1011-$G1011)>MAX(Keys!$C$62,ABS($G1011)*Keys!$C$63)),1,0) -> 0 | U1011: =IF(OR($N1011<Keys!$C$51,$N1011>Keys!$C$52),1,0) -> 0 | V1011: =IF(AND($E1011=Keys!$C$60,$N1011<>Keys!$C$51),1,0) -> 0 | W1011: =IF($L1011>Keys!$C$51,IF($K1011/$L1011>Keys!$C$52,1,0),0) -> 0 | X1011: =ABS($M1011-$S1011) -> 0
A1014: SECTION 2 - the 21 answers for the state currently selected on the About tab
A1015: This pulls the selected state's rows out of the table above. The output tab reads column B, and nothing else. Change the state name in About!B1 and these 21 numbers change with it.
A1016: Fuel | B1016: Export share for the selected state | C1016: US national share, for comparison
A1017: =Keys!$F$2 -> electricity (not used in this variable) | B1017: =INDEX($N$4:$N$1011,MATCH(About!$B$2&Keys!$C$54&$A1017,$F$4:$F$1011,0)) -> 0 | C1017: =Keys!$H$2 -> 0
A1018: =Keys!$F$3 -> hard coal | B1018: =INDEX($N$4:$N$1011,MATCH(About!$B$2&Keys!$C$54&$A1018,$F$4:$F$1011,0)) -> 0 | C1018: =Keys!$H$3 -> 0.13753988
A1019: =Keys!$F$4 -> natural gas | B1019: =INDEX($N$4:$N$1011,MATCH(About!$B$2&Keys!$C$54&$A1019,$F$4:$F$1011,0)) -> 0 | C1019: =Keys!$H$4 -> 0.19083918
A1020: =Keys!$F$5 -> nuclear | B1020: =INDEX($N$4:$N$1011,MATCH(About!$B$2&Keys!$C$54&$A1020,$F$4:$F$1011,0)) -> 0 | C1020: =Keys!$H$5 -> 0
A1021: =Keys!$F$6 -> hydro (is not a fuel) | B1021: =INDEX($N$4:$N$1011,MATCH(About!$B$2&Keys!$C$54&$A1021,$F$4:$F$1011,0)) -> 0 | C1021: =Keys!$H$6 -> 0
A1022: =Keys!$F$7 -> wind (is not a fuel) | B1022: =INDEX($N$4:$N$1011,MATCH(About!$B$2&Keys!$C$54&$A1022,$F$4:$F$1011,0)) -> 0 | C1022: =Keys!$H$7 -> 0
A1023: =Keys!$F$8 -> solar (is not a fuel) | B1023: =INDEX($N$4:$N$1011,MATCH(About!$B$2&Keys!$C$54&$A1023,$F$4:$F$1011,0)) -> 0 | C1023: =Keys!$H$8 -> 0
A1024: =Keys!$F$9 -> biomass | B1024: =INDEX($N$4:$N$1011,MATCH(About!$B$2&Keys!$C$54&$A1024,$F$4:$F$1011,0)) -> 0 | C1024: =Keys!$H$9 -> 0.74947425
A1025: =Keys!$F$10 -> petroleum gasoline | B1025: =INDEX($N$4:$N$1011,MATCH(About!$B$2&Keys!$C$54&$A1025,$F$4:$F$1011,0)) -> 0 | C1025: =Keys!$H$10 -> 0.075004052
A1026: =Keys!$F$11 -> petroleum diesel | B1026: =INDEX($N$4:$N$1011,MATCH(About!$B$2&Keys!$C$54&$A1026,$F$4:$F$1011,0)) -> 0 | C1026: =Keys!$H$11 -> 0.26691052
A1027: =Keys!$F$12 -> biofuel gasoline | B1027: =INDEX($N$4:$N$1011,MATCH(About!$B$2&Keys!$C$54&$A1027,$F$4:$F$1011,0)) -> 0 | C1027: =Keys!$H$12 -> 0.087213884
A1028: =Keys!$F$13 -> biofuel diesel | B1028: =INDEX($N$4:$N$1011,MATCH(About!$B$2&Keys!$C$54&$A1028,$F$4:$F$1011,0)) -> 0 | C1028: =Keys!$H$13 -> 0.058642381
A1029: =Keys!$F$14 -> jet fuel or kerosene | B1029: =INDEX($N$4:$N$1011,MATCH(About!$B$2&Keys!$C$54&$A1029,$F$4:$F$1011,0)) -> 0 | C1029: =Keys!$H$14 -> 0.10155994
A1030: =Keys!$F$15 -> heat (not used in this variable) | B1030: =INDEX($N$4:$N$1011,MATCH(About!$B$2&Keys!$C$54&$A1030,$F$4:$F$1011,0)) -> 0 | C1030: =Keys!$H$15 -> 0
A1031: =Keys!$F$16 -> geothermal (is not a fuel) | B1031: =INDEX($N$4:$N$1011,MATCH(About!$B$2&Keys!$C$54&$A1031,$F$4:$F$1011,0)) -> 0 | C1031: =Keys!$H$16 -> 0
A1032: =Keys!$F$17 -> lignite | B1032: =INDEX($N$4:$N$1011,MATCH(About!$B$2&Keys!$C$54&$A1032,$F$4:$F$1011,0)) -> 0 | C1032: =Keys!$H$17 -> 0
A1033: =Keys!$F$18 -> crude oil | B1033: =INDEX($N$4:$N$1011,MATCH(About!$B$2&Keys!$C$54&$A1033,$F$4:$F$1011,0)) -> 1 | C1033: =Keys!$H$18 -> 1
A1034: =Keys!$F$19 -> heavy fuel oil | B1034: =INDEX($N$4:$N$1011,MATCH(About!$B$2&Keys!$C$54&$A1034,$F$4:$F$1011,0)) -> 0 | C1034: =Keys!$H$19 -> 0.49914171
A1035: =Keys!$F$20 -> LPG propane or butane | B1035: =INDEX($N$4:$N$1011,MATCH(About!$B$2&Keys!$C$54&$A1035,$F$4:$F$1011,0)) -> 0 | C1035: =Keys!$H$20 -> 0.54955999
A1036: =Keys!$F$21 -> municipal solid waste | B1036: =INDEX($N$4:$N$1011,MATCH(About!$B$2&Keys!$C$54&$A1036,$F$4:$F$1011,0)) -> 0 | C1036: =Keys!$H$21 -> 0
A1037: =Keys!$F$22 -> hydrogen | B1037: =INDEX($N$4:$N$1011,MATCH(About!$B$2&Keys!$C$54&$A1037,$F$4:$F$1011,0)) -> 0 | C1037: =Keys!$H$22 -> 0

Sheet Checks
A1: Checks - every row must read PASS before export/deploy
A2: Identities first: checks 2 and 3 are exact by construction, so any nonzero is real evidence rather than a tolerance question. | F2: Helper block for the two label checks above: it compares the output tab's row and column names, one at a time, against the names they are supposed to carry.
A3: What is being checked | B3: What the workbook computes | C3: What it has to equal | D3: Result | F3: Fuel name it should be | G3: Output tab row name differs? 1 = problem | H3: Output tab column name differs? 1 = problem
A4: derivation rows present (COUNT of applied-diagonal column) | B4: =COUNT(Calcs!$N$4:$N$1011) -> 1008 | C4: =Keys!$C$64 -> 1008 | D4: =IF($B4=$C4,Keys!$C$71,Keys!$C$72) -> PASS | F4: =Keys!$F$2 -> electricity (not used in this variable) | G4: =IF(PoFDCtAE!$A$2<>$F4,1,0) -> 0 | H4: =IF(PoFDCtAE!B$1<>$F4,1,0) -> 0
A5: IDENTITY - denominator equals production wherever E > I (violations) | B5: =SUM(Calcs!$T$4:$T$1011) -> 0 | C5: =Keys!$C$51 -> 0 | D5: =IF($B5=$C5,Keys!$C$71,Keys!$C$72) -> PASS | F5: =Keys!$F$3 -> hard coal | G5: =IF(PoFDCtAE!$A$3<>$F5,1,0) -> 0 | H5: =IF(PoFDCtAE!C$1<>$F5,1,0) -> 0
A6: structural-zero rows forced to 0 (violations) | B6: =SUM(Calcs!$V$4:$V$1011) -> 0 | C6: =Keys!$C$51 -> 0 | D6: =IF($B6=$C6,Keys!$C$71,Keys!$C$72) -> PASS | F6: =Keys!$F$4 -> natural gas | G6: =IF(PoFDCtAE!$A$4<>$F6,1,0) -> 0 | H6: =IF(PoFDCtAE!D$1<>$F6,1,0) -> 0
A7: every applied diagonal inside [0, 1] (violations) | B7: =SUM(Calcs!$U$4:$U$1011) -> 0 | C7: =Keys!$C$51 -> 0 | D7: =IF($B7=$C7,Keys!$C$71,Keys!$C$72) -> PASS | F7: =Keys!$F$5 -> nuclear | G7: =IF(PoFDCtAE!$A$5<>$F7,1,0) -> 0 | H7: =IF(PoFDCtAE!E$1<>$F7,1,0) -> 0
A8: MIN(1,..) bound binding anywhere (should be inert on current data) | B8: =SUM(Calcs!$W$4:$W$1011) -> 0 | C8: =Keys!$C$51 -> 0 | D8: =IF($B8=$C8,Keys!$C$71,Keys!$C$72) -> PASS | F8: =Keys!$F$6 -> hydro (is not a fuel) | G8: =IF(PoFDCtAE!$A$6<>$F8,1,0) -> 0 | H8: =IF(PoFDCtAE!F$1<>$F8,1,0) -> 0
A9: tradeable fuel rows in the Keys table | B9: =COUNTIF(Keys!$I$2:$I$22,Keys!$C$58) -> 11 | C9: =Keys!$C$65 -> 11 | D9: =IF($B9=$C9,Keys!$C$71,Keys!$C$72) -> PASS | F9: =Keys!$F$7 -> wind (is not a fuel) | G9: =IF(PoFDCtAE!$A$7<>$F9,1,0) -> 0 | H9: =IF(PoFDCtAE!G$1<>$F9,1,0) -> 0
A10: structural-zero rows in the Keys table | B10: =COUNTIF(Keys!$I$2:$I$22,Keys!$C$60) -> 9 | C10: =Keys!$C$66 -> 9 | D10: =IF($B10=$C10,Keys!$C$71,Keys!$C$72) -> PASS | F10: =Keys!$F$8 -> solar (is not a fuel) | G10: =IF(PoFDCtAE!$A$8<>$F10,1,0) -> 0 | H10: =IF(PoFDCtAE!H$1<>$F10,1,0) -> 0
A11: rows held at the national value (crude oil) | B11: =COUNTIF(Keys!$I$2:$I$22,Keys!$C$59) -> 1 | C11: =Keys!$C$67 -> 1 | D11: =IF($B11=$C11,Keys!$C$71,Keys!$C$72) -> PASS | F11: =Keys!$F$9 -> biomass | G11: =IF(PoFDCtAE!$A$9<>$F11,1,0) -> 0 | H11: =IF(PoFDCtAE!I$1<>$F11,1,0) -> 0
A12: crude diagonal on the active state equals the national 1.0 | B12: =INDEX(Calcs!$B$1017:$B$1037,MATCH(Keys!$F$18,Calcs!$A$1017:$A$1037,0)) -> 1 | C12: =Keys!$C$52 -> 1 | D12: =IF($B12=$C12,Keys!$C$71,Keys!$C$72) -> PASS | F12: =Keys!$F$10 -> petroleum gasoline | G12: =IF(PoFDCtAE!$A$10<>$F12,1,0) -> 0 | H12: =IF(PoFDCtAE!J$1<>$F12,1,0) -> 0
A13: active-state read-back complete (COUNT) | B13: =COUNT(Calcs!$B$1017:$B$1037) -> 21 | C13: =Keys!$C$68 -> 21 | D13: =IF($B13=$C13,Keys!$C$71,Keys!$C$72) -> PASS | F13: =Keys!$F$11 -> petroleum diesel | G13: =IF(PoFDCtAE!$A$11<>$F13,1,0) -> 0 | H13: =IF(PoFDCtAE!K$1<>$F13,1,0) -> 0
A14: output matrix row labels match the Keys fuel table (mismatches) | B14: =SUM($G$4:$G$24) -> 0 | C14: =Keys!$C$51 -> 0 | D14: =IF($B14=$C14,Keys!$C$71,Keys!$C$72) -> PASS | F14: =Keys!$F$12 -> biofuel gasoline | G14: =IF(PoFDCtAE!$A$12<>$F14,1,0) -> 0 | H14: =IF(PoFDCtAE!L$1<>$F14,1,0) -> 0
A15: output matrix column labels match the Keys fuel table (mismatches) | B15: =SUM($H$4:$H$24) -> 0 | C15: =Keys!$C$51 -> 0 | D15: =IF($B15=$C15,Keys!$C$71,Keys!$C$72) -> PASS | F15: =Keys!$F$13 -> biofuel diesel | G15: =IF(PoFDCtAE!$A$13<>$F15,1,0) -> 0 | H15: =IF(PoFDCtAE!M$1<>$F15,1,0) -> 0
A16: output matrix total equals the sum of its diagonal (off-diagonals are 0) | B16: =ROUND(SUM(PoFDCtAE!$B$2:$V$22)-SUM(Calcs!$B$1017:$B$1037),9) -> 0 | C16: =Keys!$C$51 -> 0 | D16: =IF($B16=$C16,Keys!$C$71,Keys!$C$72) -> PASS | F16: =Keys!$F$14 -> jet fuel or kerosene | G16: =IF(PoFDCtAE!$A$14<>$F16,1,0) -> 0 | H16: =IF(PoFDCtAE!N$1<>$F16,1,0) -> 0
F17: =Keys!$F$15 -> heat (not used in this variable) | G17: =IF(PoFDCtAE!$A$15<>$F17,1,0) -> 0 | H17: =IF(PoFDCtAE!O$1<>$F17,1,0) -> 0
A18: informational: state-fuel cells changed from the national file | B18: =SUM(Calcs!$O$4:$O$1011) -> 484 | F18: =Keys!$F$16 -> geothermal (is not a fuel) | G18: =IF(PoFDCtAE!$A$16<>$F18,1,0) -> 0 | H18: =IF(PoFDCtAE!P$1<>$F18,1,0) -> 0
