Workbook

Sheet About
A1: Web App Data | B1: Rhode Island | C1: 46294 | G1: abrv | H1: state
B2: =_xlfn.XLOOKUP(B1,H:H,G:G,0,0,1) -> RI | C2: =_xlfn.XLOOKUP(B2,G:G, H:H, 0,0,1) -> Rhode Island | G2: AK | H2: Alaska
A3: This spreadsheet contains data that is used to populate the web application interface | G3: AL | H3: Alabama
A4: for the Energy Policy Simulator. The data in other tabs in this spreadsheet are used | G4: AR | H4: Arkansas
A5: to establish the policy levers, lever bounds, descriptive text for pop-over | G5: AZ | H5: Arizona
A6: panels, output graphs, and reference scenarios available in the web app. | G6: CA | H6: California
G7: CO | H7: Colorado
A8: A live version of the web application interface powered by a copy of this model | G8: CT | H8: Connecticut
A9: can be found at: | G9: DC | H9: DC
A10: https://www.energypolicy.solutions | G10: DE | H10: Delaware
G11: FL | H11: Florida
A12: You are unlikely to need to use or change the contents of this spreadsheet, unless | G12: GA | H12: Georgia
A13: you are adapting the Energy Policy Simulator to a new country and desire | G13: HI | H13: Hawaii
A14: a web application interface customized for your country-specific model version. | G14: IA | H14: Iowa
G15: ID | H15: Idaho
A16: Checks for Policy ID Number Validity | G16: IL | H16: Illinois
A17: Max policy ID number in use | B17: =MAX(PolicyLevers!H:H) -> 2799 | G17: IN | H17: Indiana
A18: Lowest duplicate ID number | B18: {=IF(MIN(IF(COUNTIF(PolicyLevers!$H$2:$H$2053,PolicyLevers!$H$2:$H$2053)>1,PolicyLevers!$H$2:$H$2053, ""))=0,"No duplicate ID numbers",MIN(IF(COUNTIF(PolicyLevers!$H$2:$H$2053,PolicyLevers!$H$2:$H$2053)>1,PolicyLevers!$H$2:$H$2053, "")))} -> No duplicate ID numbers | G18: KS | H18: Kansas
A19: Row of first policy missing a valid ID number | B19: {=IF(MIN(IF((NOT(ISNUMBER(PolicyLevers!$H$2:$H$2053)))*(ISTEXT(PolicyLevers!$I$2:$I$2053)),ROW(PolicyLevers!$H$2:$H$2053)))=0,"No missing ID numbers",MIN(IF((NOT(ISNUMBER(PolicyLevers!$H$2:$H$2053)))*(ISTEXT(PolicyLevers!$I$2:$I$2053)),ROW(PolicyLevers!$H$2:$H$2053))))} -> No missing ID numbers | G19: KY | H19: Kentucky
G20: LA | H20: Louisiana
A21: Customizing Policy Levers | G21: MA | H21: Massachusetts
A22: Define most policy properties on the "Policy Characteristics" tab. | G22: MD | H22: Maryland
A23: Specify the subscripted elements of each policy and which are enabled/disabled on the "PolicyLevers" tab. | G23: ME | H23: Maine
A24: On the PolicyLevers tab, only manually edit the cells under the green column headers. Simply extend the | G24: MI | H24: Michigan
A25: existing formulas up or down to fill cells under the red headers on that tab. | G25: MN | H25: Minnesota
G26: MO | H26: Missouri
A27: Notes on Meaning of Blank Cells on the Policy Characteristics Tab | G27: MS | H27: Mississippi
A28: Leave the "Policy Schedule Subscript" cell blank to deny the ability to edit the implementation | G28: MT | H28: Montana
A29: schedule for a lever. This should generally only be done for levers that do not use an | G29: NC | H29: North Carolina
A30: implementation schedule: the toggle to Non-BAU Mandated Capacity Construction | G30: ND | H30: North Dakota
A31: (which has its own schedule built into its input data) and the Nuclear Lifetime Extension | G31: NE | H31: Nebraska
A32: (which simply delays retirements that would occur in the BAU Retirements input data). | G32: NH | H32: New Hampshire
G33: NJ | H33: New Jersey
A34: Leave the "Policy Group" cell blank to exclude a lever from wedge diagrams and abatement cost curves. | G34: NM | H34: New Mexico
A35: This should always be done for "Control Settings" (which affect both the BAU and policy cases), | G35: NV | H35: Nevada
A36: and should generally never be done for actual policy levers. | G36: NY | H36: New York
G37: OH | H37: Ohio
A38: Leave the "URL for "How the model handles this policy" links" cell blank to exclude this link from | G38: OK | H38: Oklahoma
A39: the policy's pop-over pane. You should generally do this whenever there is no on-topic place | G39: OR | H39: Oregon
A40: in the documentation to which to send a user. | G40: PA | H40: Pennsylvania
...

Sheet Policy Characteristics
A1: This tab contains information about each policy that does not vary by subscripted element of that policy.
A2: It matches policies to the listing in the "PolicyLevers" tab using the "Vensim Variable Name" column.
A3: Sector | B3: Short Name | C3: Vensim Variable Name | D3: Policy Group | E3: Policy Schedule Subscript | F3: Min Slider Value | G3: Max Slider Value | H3: Slider Step Size | I3: Units | J3: Text for Pop-Over Panel Description | K3: URL for "How the model handles this policy" links | L3: URL for "How to design this policy well" links | M3: Source for Guidance Text (if any) | N3: Source for Max Slider Value (if any)
A4: Agriculture, Land Use, and Forestry | B4: Afforestation and Reforestation | C4: Fraction of Afforestation and Reforestation Achieved | D4: Afforestation and Reforestation | E4: land afforestation and reforestation | F4: -3 | G4: 1 | H4: 0.01 | I4: % of potential achieved | J4: **Description:** This policy increases the sequestration of CO2 by planting forests. Planted forests are assumed to be managed with best practices and are not used for timber harvesting. A negative values implies less sequestration compared to the Current Policies scenario. | K4: lulucf.html#aff-ref | L4: afforestation-and-reforestation.html | M4: Calculated from model data; see the relevant variable(s) in the InputData folder for source information. | N4: Ross W. Gorte, 2009, "U.S. Tree Planting for Carbon Sequestration," Congressional Research Service, https://www.fas.org/sgp/crs/misc/R40562.pdf, p.3, paragraph 1
A5: Agriculture, Land Use, and Forestry | B5: Avoid Deforestation | C5: Fraction of Avoided Deforestation Achieved | D5: Avoid Deforestation | E5: land avoid deforestation | F5: 0 | G5: 1 | H5: 0.01 | I5: % of potential achieved | J5: **Description:** This policy prevents clear cutting of forests that would otherwise be cleared. Preserved forests are assumed to be managed with best practices. | K5: lulucf.html#avoid-def | L5: avoid-deforestation.html
A6: Agriculture, Land Use, and Forestry | B6: Cropland and Rice Measures | C6: Fraction of Cropland and Rice Measures Achieved | D6: Cropland and Rice Measures | E6: indst cropland and rice measures | F6: 0 | G6: 1 | H6: 0.01 | I6: % of potential achieved | J6: **Description:** This policy reduces CH4 and N2O emissions from agriculture through cropland management practices, such as improved crop rotations, reduced soil tillage, and improvements in fertilizer composition and application. Measures particular to rice cultivation include improved flooding practices that avoid anaerobic, methane-forming conditions. | K6: industry-ag-main.html#cropland | L6: cropland-management.html | M6: Calculated from model data; see the relevant variable(s) in the InputData folder for source information.
A7: Agriculture, Land Use, and Forestry | B7: Forest Set-Asides | C7: Fraction of Forest Set Asides Achieved | D7: Forest Set-Asides | E7: land forest set asides | F7: 0 | G7: 1 | H7: 0.01 | I7: % of potential achieved | J7: **Description:** This policy avoids the release of CO2 from forests by reducing timber harvesting. // **Guidance for setting values:** A 100% setting of this lever reduces timber harvesting by 2% of the BAU amount per year, reaching a roughly 70% reduction in timber harvesting by 2050. | K7: lulucf.html#set-asides | L7: forest-set-asides.html | M7: Calculated from model data; see the relevant variable(s) in the InputData folder for source information.
A8: Agriculture, Land Use, and Forestry | B8: Grassland Restoration and Avoided Conversion | C8: Fraction of Forest Restoration Achieved | D8: Grassland Restoration and Avoided Conversion | E8: land forest restoration | F8: 0 | G8: 1 | H8: 0.01 | I8: % of potential achieved | J8: **Description:** This policy increases CO2 sequestration by avoiding the conversion of grasslands and restoring grassland areas. | L8: forest-restoration.html | M8: See file PLANAbPiaSY
A9: Agriculture, Land Use, and Forestry | B9: Improved Forest Management | C9: Fraction of Improved Forest Management Achieved | D9: Improved Forest Management | E9: land forest management | F9: -1.5 | G9: 1 | H9: 0.01 | I9: % of potential achieved | J9: **Description:** This policy increases CO2 sequestration by forests through improved forest management practices. A negative values implies less sequestration compared to the Current Policies scenario. | K9: lulucf.html#forest-mgmt | L9: improved-forest-management.html | M9: Calculated from model data; see the relevant variable(s) in the InputData folder for source information.
A10: Agriculture, Land Use, and Forestry | B10: Improved Soil Measures | C10: Fraction of CO2 Storage Through Tillage Practices | D10: Improved Soil Measures | E10: indst tillage | F10: 0 | G10: 1 | H10: 0.01 | I10: % of potential achieved | J10: **Description:** This policy stores CO2 in agricultural soils through improved tillage practices, retiring organic and marginal soils, and establishing windbreaks/shelterbelts.
A11: Agriculture, Land Use, and Forestry | B11: Livestock Measures | C11: Fraction of Livestock Measures Achieved | D11: Livestock Measures | E11: indst livestock measures | F11: 0 | G11: 1 | H11: 0.01 | I11: % of potential achieved | J11: **Description:** This policy reduces greenhouse gas emissions from agriculture through livestock-related measures, such as feed supplements or drugs to prevent enteric methane formation. | K11: industry-ag-main.html#livestock | L11: livestock-measures.html | M11: Calculated from model data; see the relevant variable(s) in the InputData folder for source information.
A12: Agriculture, Land Use, and Forestry | B12: Shift to Non-Animal Products | C12: Percent Animal Products Shifted to Nonanimal Products | D12: Shift to Non-Animal Products | E12: indst shift to nonanimal products | F12: 0 | G12: 1 | H12: 0.01 | I12: % reduction in animal products | J12: **Description:** This policy causes animal products to be substituted for non-animal products, which might be achieved by changes in consumer preferences or by changes in costs of agricultural products (such as by redirecting subsidies currently paid to farmers who raise animals or feed crops to farmers growing fruits, vegetables, and other plant-based foods for human consumption). Moderate settings of this policy lever do not imply a vegan diet: for instance, a 50% setting could represent each individual consuming half as many animal products, rather than half of the population consuming no animal products. // **Guidance for setting values:** According to OECD statistics, the U.S. has the highest per-capita meat consumption in the world, at 99 kg/person/year. If the U.S. were to achieve a rate similar to that in Europe (70 kg/person/yr), Japan (36 kg/person/yr), or India (3 kg/person/yr), this would be a reduction of 29% (Europe), 64% (Japan), or 97% (India) respectively. | L12: shift-to-non-animal-products.html | M12: https://en.wikipedia.org/wiki/List_of_countries_by_meat_consumption_per_capita (article revision 00:12, 22 Feb 2019)
A13: Agriculture, Land Use, and Forestry | B13: Wetland Restoration | C13: Fraction of Peatland Restoration Achieved | D13: Wetland Restoration | E13: land peatland restoration | F13: 0 | G13: 1 | H13: 0.01 | I13: % of potential achieved | J13: **Description:** This policy increases CO2 sequestration by restoring wetlands and riparian forest buffers. | L13: peatland-restoration.html | M13: https://www.usda.gov/sites/default/files/documents/White_Paper_WEB71816.pdf
A14: Buildings and Appliances | B14: Building Component Electrification | C14: Fraction of New Bldg Components Shifted to Other Fuels | D14: Building Component Electrification | E14: bldgs new component fuel shifting | F14: 0 | G14: 1 | H14: 0.01 | I14: % of newly sold non-electric building components | J14: **Description:** This policy replaces the specified fraction of newly sold non-electric building components of the selected type(s) in buildings of the selected type(s) with electricity-using components. | K14: buildings-sector-main.html#component-elec | L14: building-component-electrification.html | M14: EIA AEO
A15: Buildings and Appliances | B15: Building Energy Efficiency Standards | C15: Reduction in E Use Allowed by Component Eff Std | D15: Building Energy Efficiency Standards | E15: bldgs efficiency standards | F15: 0 | G15: 0.75 | H15: 0.01 | I15: % reduction in energy use | J15: **Description:** This policy tightens energy efficiency standards for the selected component(s) in the selected building type(s). The policy only applies to newly sold components each year (whether for new buildings or replacement of old components of existing buildings). // **Guidance for setting values:** In "Assessment of Electricity Savings in the U.S. Achievable through New Appliance/Equipment Efficiency Standards and Building Efficiency Codes, 2010-2025" (2011), the Edison Foundation considered a 30% reduction in whole-building energy use (moderate case) and 40-45% (aggressive case) relative to BAU from 2010 to 2025. | K15: buildings-sector-main.html#eff-stds | L15: building-energy-efficiency-standards.html | M15: Edison Foundation, 2011, "Assessment of Electricity Savings in the U.S. Achievable through New Appliance/Equipment Efficiency Standards and Building Efficiency Codes (2010 - 2025)", http://www.edisonfoundation.net/iei/Documents/IEE_CodesandStandardsAssessment_2010-2025_UPDATE.pdf, Page B-2, Table B-1. | N15: Itron, 2007, "ASSESSMENT OF LONG-TERM ELECTRIC ENERGY EFFICIENCY POTENTIAL IN CALIFORNIA’S RESIDENTIAL SECTOR," http://www.energy.ca.gov/2007publications/CEC-500-2007-002/CEC-500-2007-002.PDF, p.33, Table 5-1
A16: Buildings and Appliances | B16: Contractor Training | C16: Boolean Improved Contractor Edu and Training | D16: Contractor Training | E16: bldgs contractor training | F16: 0 | G16: 1 | H16: 1 | I16: on/off | J16: **Description:** This policy represents a program to train contractors in energy-efficient products and installation practices. This covers activities such as air sealing, building framing, and choice and application of insulation. This policy affects newly sold building envelope components, which reduce the energy use of heating, cooling, and ventilation systems in buildings by 3.7% (based on a 2006 study from the Energy Center of Wisconsin). | K16: buildings-sector-main.html#contractor-ed | L16: contractor-training.html
A17: Buildings and Appliances | B17: Distributed Solar Capacity Requirement | C17: Min Required Rooftop Solar Capacity | D17: Distributed Solar Promotion | E17: bldgs min req rooftop solar | F17: 0 | G17: 600000 | H17: 5000 | I17: MW | J17: **Description:** This policy requires at least the specified capacity of distributed solar be built by the model.
A18: Buildings and Appliances | B18: Distributed Solar Carve-Out | C18: Min Fraction of Total Elec Demand to be Met by Distributed Solar PV | D18: Distributed Solar Promotion | E18: bldgs min fraction distributed solar | F18: 0 | G18: =ROUND(MaxBoundCalculations!B172,2) -> 0.24 | H18: 0.005 | I18: minimum % elec from solar | J18: **Description:** This policy requires at least the specified percentage of total retail electricity demand to be generated by residential and commercial buildings' distributed solar systems (typically rooftop PV). // **Guidance for setting values:** Colorado has established a 3% carve-out for 2020 (though it includes non-solar on-site sources). | K18: buildings-sector-main.html#solar-carve-out | L18: solar-carve-out.html | M18: MASSACHUSETTS: http://www.mass.gov/eea/energy-utilities-clean-tech/renewable-energy/solar/rps-solar-carve-out/current-status-of-the-rps-solar-carve-out-program.html COLORADO: http://www.seia.org/research-resources/rps-solar-carve-out-colorado | N18: RMI, 2011, "Reinventing Fire Electricity Sector Methodology," http://www.rmi.org/cms/Download.aspx?id=10765&file=Reinventing+Fire+Electricity+Sector+Methodology.pdf&title=Reinventing+Fire+Electricity+Sector+Methodology, Page 11, 2050 Generation by Case
A19: Buildings and Appliances | B19: Distributed Solar Subsidy | C19: Additional Perc Subsidy for Distributed Solar PV Capacity | D19: Distributed Solar Promotion | E19: bldgs distributed solar subsidy | F19: 0 | G19: 0.5 | H19: 0.01 | I19: % of PV system cost | J19: **Description:** This policy causes the government to reimburse building owners for an additional percentage of the cost of new distributed solar PV capacity that is installed on or around buildings. // **Guidance for setting values:** The Inflation Reduction Act included a 30% tax credit for residential solar, although it was cut short by the One Big Beautiful Bill Act. Commercial buildings also qualified for the utility-scale 30% investment tax credit. | K19: buildings-sector-main.html#distributed-solar-subsidy | L19: distributed-solar-subsidy.html | M19: Department of Energy. Business Energy Investment Tax Credit (ITC). http://energy.gov/savings/business-energy-investment-tax-credit-itc
A20: Buildings and Appliances | B20: Improved Labeling | C20: Boolean Improved Device Labeling | D20: Improved Labeling | E20: bldgs device labeling | F20: 0 | G20: 1 | H20: 1 | I20: on/off | J20: **Description:** This policy represents a program requiring newly sold heating systems, cooling and ventilation systems, and appliances to feature prominent, well-designed labels highlighting their energy efficiencies. The policy reduces energy consumption of newly sold building components of these types by 10%. | K20: buildings-sector-main.html#device-labeling | L20: improved-labeling.html | M20: none
A21: Buildings and Appliances | B21: Non BAU Distributed Solar Capacity | C21: Boolean Use Non BAU Distributed Solar Capacity | D21: Distributed Solar Promotion | E21: non BAU dist solar | F21: 0 | G21: 1 | H21: 1 | I21: on/off | J21: **Description:** This policy adds or subtracts an amount of distributed solar according to an alternate input data file. For the U.S., this file is configured to remove the amount of incremental distributed solar deployment expected from the Inflation Reduction Act. //
A22: Buildings and Appliances | B22: Rebate for Efficient Products | C22: Boolean Rebate Program for Efficient Components | D22: Rebate for Efficient Products | E22: bldgs rebate | F22: 0 | G22: 1 | H22: 1 | I22: on/off | J22: **Description:** This policy represents a modest rebate paid to customers who purchase energy-efficient building equipment of the selected type(s). Typical rebate amounts represented by this policy are $50-100 for a clothes washer and $25-50 for a dishwasher or refrigerator. | K22: buildings-sector-main.html#rebate | L22: rebate-for-efficient-products.html
A23: Buildings and Appliances | B23: Retrofit Existing Buildings | C23: Share of Preexisting Buildings Subject to Retrofitting | D23: Increased Retrofitting | E23: bldgs retrofitting | F23: 0 | G23: 0.5 | H23: 0.01 | I23: % of existing buildings | J23: **Description:** This policy retrofits the specified percentage of buildings to more efficient heating, cooling, and envelope components. // **Guidance for setting values:** Without additional policy, by 2050, roughly 90% of the preexisting residential buildings and 85% of commercial buildings will survive without major renovations. This policy renovates them more quickly than they would have otherwise, improving the efficiency of building stock. A policy value of 100% causes all preexisting buildings to be renovated along the schedule specified by the user. If required by 2050, for example, this policy would induce retrofits of the 90% of residential buildings and 85% of commercial buildings not overhauled in the model baseline. A value of 50% in 2050 would renovate 45% of preexisting residential and 42.5% of preexisting commercial buildings, and so forth. | K23: buildings-sector-main.html#retrofitting | L23: increased-retrofitting.html | M23: Calculated from model data; see the relevant variable(s) in the InputData folder for source information.
A24: Carbon Removal | B24: Direct Air Capture | C24: Fraction of Direct Air Capture Potential Achieved | D24: Carbon Dioxide Removal | E24: geoeng direct air capture | F24: 0 | G24: 1 | H24: 0.01 | I24: % of potential achieved | J24: **Description:** This policy causes direct air capture (DAC) technology to be used to remove carbon dioxide from the atmosphere. The modeled technology is based on hydroxide sorbents, as this is the most mature DAC technology. Alternatives (such as amine-based technologies) are unlikely to have a perceptible impact by 2050, the last year of the EPS model run. Note that all DAC technologies, even hydroxide sorbents, have their greatest potential effects after 2050, which cannot be seen in a model run that ends in 2050. (DAC refers only to mechanical methods of carbon dioxide removal, not afforestation and other land use measures. For those measures, see the policy levers in the "Agriculture, Land Use, and Forestry" category.) // **Guidance for setting values:** A 100% setting implies large DAC research and development investments starting today, and deployment in line with the published Long-Term Strategy of the United States: Pathways to Net-Zero Greenhouse Gas Emissions by 2050 (roughly 350 MMT in 2050). | K24: direct-air-capture.html#dac | L24: direct-air-capture.html | M24: Realmonte et al., 2019, An inter-model assessment of the role of direct air capture in deep mitigation pathways, https://www.nature.com/articles/s41467-019-10842-5, Table 2, https://static-content.springer.com/esm/art%3A10.1038%2Fs41467-019-10842-5/MediaObjects/41467_2019_10842_MOESM1_ESM.pdf, Supplementary materials, Fig 3
A25: Carbon Removal | B25: Enhanced Rock Weathering | C25: Fraction of Enhanced Rock Weathering Potential Achieved | D25: Carbon Dioxide Removal | E25: geoeng enhanced rock weathering | F25: 0 | G25: 1 | H25: 0.01 | I25: % of potential achieved | J25: **Description:** This policy causes deployment of enhanced rock weathering practices to absorb CO2 from the atmosphere. We use data from Fuhrman et al., which assumes application of crushed basalt to croplands. // **Guidance for setting values:** A 100% setting implies rock application to roughly 45 million acres. | M25: Strefler et al., 2018, (used as a source on total acrege for our Fuhrman et al. data, https://content.cld.iop.org/journals/1748-9326/13/3/034010/revision2/ERL_034010_SD.pdf?Expires=1720629928&Signature=jHMnzWhptSu-2LByE4KdFSDS-DnRp9gzhnqimxxA1RXqsDDTo015nrsWRJqNRyNqExM59e0IjQOWRK1k6zkpTdrMxwQTaE1yD5yczeGsUNqiCqXYn5Zfj08uJQ-HIiuHek1qKCp8Njc9HMrxocyo~nIcf7eRRWkaRfOclfayd-52YV1Dgwv9N~rc2fbap9xGqOB5p8gCkQDmkXX2z5QnMMIkGBr-tGCrxZUxe0CuCxiYpVtI3rRDXkIgQamshSf4yA1QfcIwukn3F564By~Ztx0vUTUvbT7CIcfvUNkYkQDSKpzzi50D2Nv7usXFRIyOckZu1AJWhhzHbzcwburKrQ__&Key-Pair-Id=KL1D8TIY3N7T8
A26: Control Settings | B26: COVID-19 Recession | C26: EGGRA Boolean Use Exogenous GDP Growth Rate Adjustment | E26: settings exogenous GDP adjustment | F26: 0 | G26: 1 | H26: 1 | I26: on/off | J26: **Description:** This control setting is not used in the U.S. EPS at present, but it could be used to enable or disable the impacts of a or disables the GDP impact of a recession or other GDP-impacting event not accounted for in the energy use input data files. It was previously used to model the recession caused by SARS-CoV-2 (COVID-19).
A27: Control Settings | B27: Exclude Elec Exports from Elec Portfolio Stds | C27: BEEEfEPS Boolean Exclude Elec Exports from Elec Portfolio Stds | D27: Clean Electricity Standard | F27: 0 | G27: 1 | H27: 1 | I27: on/off | J27: **Description:** This policy lever excludes exported electricity from the clean electricity standard requirements.
A28: Control Settings | B28: Non BAU First Year | C28: Boolean Use Non BAU First Year Impacting Future Policies | F28: 0 | G28: 1 | H28: 1 | I28: on/off | J28: **Description:** When a government designs a clean electricity standard or renewable portfolio standard, they typically offer utilities time to achieve compliance by scheduling increases in stringency far in advance. We assume no additional compliance with these policies in historical years, which are calibrated. But in a policy scenario, this lever can be used to switch out the first year behavior can reflect future policies to a different year, for example to examine "what if" scenarios around changes in political administrations.
A29: Control Settings | B29: Use 20-Year GWP Values | C29: BUTYGV Boolean Use Twenty Year GWP Values | F29: 0 | G29: 1 | H29: 1 | I29: on/off | J29: **Description:** Non-CO2 GHGs are converted to CO2 equivalent by comparing their warming power per unit mass to that of CO2. This ratio is called a gas' Global Warming Potential (GWP). Since different GHGs have different atmospheric lifetimes, the ratio is not static, so GWP values are defined as the cumulative warming effect over a particular timeframe. By default, the EPS uses 100-year GWP values, i.e., reflecting the ratio of the warming caused by a non-CO2 GHG to CO2 over a 100-year period after the pollutant is emitted. This is the most common timeframe used in policymaking and in the literature. Enabling this control setting switches to 20-year GWP values, the second-most-common timeframe used in the literature. Except for F-gases, non-CO2 GHGs will appear more important when using 20-year GWP values because they have shorter atmospheric lifetimes than CO2. // Note that F-gases in the model are a mixture of many gases, not a single chemical species. Input data on F-gases was available in 100-year GWP terms and cannot be converted to 20-year GWP values because of the unknown breakdown of the F-gas mixture. _Therefore, F-gases are always expressed in 100-year GWP terms, ignoring this lever setting._
A30: Cross-Sector | B30: Carbon Price | C30: Additional Carbon Tax Rate | D30: Carbon Price | E30: cross carbon tax | F30: 0 | G30: 300 | H30: 5 | I30: =UnitControlCenter!$B$55 -> $/metric ton CO2e | J30: **Description:** This policy applies a price on fuels used in the selected sector(s) based on their greenhouse gas emissions. It also increases the base cost of capital equipment (e.g., vehicles, power plants, building components) according to their embedded carbon content. When applied to the Industry Sector, the tax **is** levied on greenhouse gas emissions from non-energy industrial and agricultural processes by default, but these emissions sources can be exempted from the tax by enabling the policy lever "Exempt Process Emissions from C Tax." Note that by default, a carbon price will not include a border adjustment, but a border adjustment can be enabled using the policy lever "Toggle Carbon Tax Border Adjustment." // **Guidance for setting values:** The U.S. government's revised Social Cost of Carbon estimates for the year 2050 range from $200 to $520 per ton (in inflation-adjusted 2020 dollars), depending on one's choice of discount rate. | K30: fuels.html#carbon-tax | L30: carbon-tax.html | M30: U.S. EPA, 2015, "The Social Cost of Carbon", https://www.epa.gov/climatechange/social-cost-carbon, Row "2050". (For source for adjustment to 2018 dollars, see cpi.xlsx in InputData.) | N30: U.S. EPA, 2016, "Social Cost of CO2, 2015-2020," https://www.epa.gov/climatechange/social-cost-carbon
A31: Cross-Sector | B31: Change in Fuel Prices | C31: Policy Driven Change in Fuel Price | D31: Change in Fuel Prices | E31: cross fuel price change | F31: -0.5 | G31: 0.5 | H31: 0.01 | I31: % change in fuel price | J31: **Description:** The EPS endogenously calculates adjusts electricity prices in response to policies that shift supply, demand, and costs. But it does not endogenously adjust the price of other fuels. This lever allows the user to exogenously adjust prices to represent economic changes from other policies.
A32: Cross-Sector | B32: End Existing Subsidies | C32: Percent Reduction in BAU Subsidies | D32: End Existing Subsidies | E32: cross reduce BAU subsidies | F32: 0 | G32: 1 | H32: 0.01 | I32: % reduction in BAU subsidies | J32: **Description:** This policy reduces the subsidies paid for the production of the selected energy source(s) (relative to the BAU case). Note that some subsidies affect the cost of fuel (such as coal and natural gas), while some subsidies are for electricity production or capacity construction (federal Production Tax Credits and Investment Tax Credits). | K32: fuels.html#end-subsidies | L32: end-existing-subsidies.html | M32: Calculated from model data; see the relevant variable(s) in the InputData folder for source information.
A33: Cross-Sector | B33: Exempt Non-CO2 Emissions from C Tax | C33: Toggle Whether Carbon Tax Affects Non CO2 Emissions | E33: cross toggle whether carbon tax affects non CO2 emissions | F33: 0 | G33: 1 | H33: 1 | I33: on/off | J33: **Description:** By default, the carbon tax applies to CO2 and non-CO2 emissions. This policy exempts non-CO2 emissions, meaning the carbon tax will only apply to CO2 emissions. | K33: fuels.html#carbon-tax | L33: carbon-tax.html
A34: Cross-Sector | B34: Exempt Process Emissions from C Tax | C34: BEPEfCT Boolean Exempt Process Emissions from Carbon Tax | E34: cross toggle whether carbon tax affects process emissions | F34: 0 | G34: 1 | H34: 1 | I34: on/off | J34: **Description:** Turning this policy lever on prevents the carbon tax from being levied on process emissions from the selected industry categories. (Process emissions are non-energy greenhouse gas emissions from industrial and agricultural operations, for example emissions released due to chemical reactions during cement production). By default, we exempt agriculture and water and waste process emissions, as these categories are generally not covered by carbon tax proposals. | K34: fuels.html#carbon-tax | L34: carbon-tax.html
A35: Cross-Sector | B35: Fixed Energy Prices | C35: Toggle Whether Policies Affect Energy Prices | D35: Fixed Energy Prices | E35: cross toggle whether policies affect energy prices | F35: 0 | G35: 1 | H35: 1 | I35: on/off
A36: Cross-Sector | B36: Fuel Price Deregulation | C36: Fuel Price Deregulation | D36: Fuel Price Deregulation | E36: cross fuel price deregulation | F36: 0 | G36: 1 | H36: 0.01 | I36: % of price deregulated | J36: **Description:** This policy causes the price of the selected fuel(s) for domestic buyers to approach international market prices. // **Guidance for setting values:** A value of 100% causes domestic fuel prices to equal international market prices, increasing the domestic price by roughly X% in 2050. | K36: fuels.html#fuel-price-deregulation
A37: Cross-Sector | B37: Fuel Taxes or Subsidies | C37: Additional Fuel Tax or Subsidy Rate by Fuel | D37: Fuel Taxes or Subsidies | E37: cross fuel tax | F37: -0.9 | G37: 0.9 | H37: 0.01 | I37: % of BAU price | J37: **Description:** This policy changes the tax rate for the selected fuel type(s). It is expressed as a percentage of the BAU Scenario price, which includes sales and excise taxes. To increase the tax rate, set a positive value. To reduce the BAU tax rate (or to apply a subsidy), set a negative value. // **Guidance for setting values:** In 2012, the national average sales tax rate was 6.8% and the national average tax rate on gasoline was 14%. | K37: fuels.html#fuel-taxes | L37: fuel-taxes.html | M37: AVG SALES TAX: The Sales Tax Clearinghouse, FAQ, https://thestc.com/FAQ.stm, Question "What is the average sales tax nationally?" AVG GASOLINE TAX: Energy Information Administration, 2014, Annual Energy Outlook 2014, http://www.eia.gov/forecasts/aeo/supplement/suptab_130.xlsx, Supplement Table 130.
A38: Cross-Sector | B38: Non BAU Carbon Tax Industry Qualification | C38: Boolean Use Non BAU Carbon Tax Industry Category Qualification | F38: 0 | G38: 1 | H38: 1 | I38: on/off | J38: **Description:** This lever determines which industry categories are captured under the scope of a carbon tax. In some regions, only certain industries are covered by a carbon tax or cap.
A39: Cross-Sector | B39: Non BAU Carbon Tax Vehicle Qualification | C39: Boolean Use Non BAU Carbon Tax Vehicle Type Qualification | F39: 0 | G39: 1 | H39: 1 | I39: on/off | J39: **Description:** This lever determines which vehicle types are captured under the scope of a carbon tax. In some regions, only certain vehicle types are covered by a carbon tax or cap.
A40: Cross-Sector | B40: Non BAU CBAM Industry Qualification | C40: Boolean Use Non BAU Carbon Tax Border Adjustment Industry Qualification | F40: 0 | G40: 1 | H40: 1 | I40: on/off | J40: **Description:** This lever determines which industry categories are captured under the scope of a carbon border adjustment mechanism. In some regions, only certain industries are covered by a border mechanism.
...

Sheet PolicyLevers
A1: Sector | B1: Short Name | C1: Vensim Variable Name | D1: Subscript 1 Value | E1: Subscript 2 Value | F1: Subscript 1 Display Name | G1: Subscript 2 Display Name | H1: Policy ID Number | I1: Include in Web App | J1: Policy Group | K1: Policy Schedule Subscript | L1: Min Slider Value | M1: Max Slider Value | N1: Slider Step Size | O1: Units | P1: Text for Pop-Over Panel Description | Q1: URL for "How the model handles this policy" links | R1: URL for "How to design this policy well" links | S1: Short Description | T1: Policy Schedule Graph Variable
A2: =IF(ISBLANK(INDEX('Policy Characteristics'!A:A,MATCH($C2,'Policy Characteristics'!$C:$C,0))),"",INDEX('Policy Characteristics'!A:A,MATCH($C2,'Policy Characteristics'!$C:$C,0))) -> Buildings and Appliances | B2: =IF(ISBLANK(INDEX('Policy Characteristics'!B:B,MATCH($C2,'Policy Characteristics'!$C:$C,0))),"",INDEX('Policy Characteristics'!B:B,MATCH($C2,'Policy Characteristics'!$C:$C,0))) -> Building Component Electrification | C2: Fraction of New Bldg Components Shifted to Other Fuels | D2: heating | E2: urban residential | F2: Heating | G2: Urban Residential | H2: 435 | I2: Yes | J2: =IF(ISBLANK(INDEX('Policy Characteristics'!D:D,MATCH($C2,'Policy Characteristics'!$C:$C,0))),"",INDEX('Policy Characteristics'!D:D,MATCH($C2,'Policy Characteristics'!$C:$C,0))) -> Building Component Electrification | K2: =IF(ISBLANK(INDEX('Policy Characteristics'!E:E,MATCH($C2,'Policy Characteristics'!$C:$C,0))),"",INDEX('Policy Characteristics'!E:E,MATCH($C2,'Policy Characteristics'!$C:$C,0))) -> bldgs new component fuel shifting | L2: =IF(ISBLANK(INDEX('Policy Characteristics'!F:F,MATCH($C2,'Policy Characteristics'!$C:$C,0))),"",INDEX('Policy Characteristics'!F:F,MATCH($C2,'Policy Characteristics'!$C:$C,0))) -> 0 | M2: =IF(ISBLANK(INDEX('Policy Characteristics'!G:G,MATCH($C2,'Policy Characteristics'!$C:$C,0))),"",INDEX('Policy Characteristics'!G:G,MATCH($C2,'Policy Characteristics'!$C:$C,0))) -> 1 | N2: =IF(ISBLANK(INDEX('Policy Characteristics'!H:H,MATCH($C2,'Policy Characteristics'!$C:$C,0))),"",INDEX('Policy Characteristics'!H:H,MATCH($C2,'Policy Characteristics'!$C:$C,0))) -> 0.01 | O2: =IF(ISBLANK(INDEX('Policy Characteristics'!I:I,MATCH($C2,'Policy Characteristics'!$C:$C,0))),"",INDEX('Policy Characteristics'!I:I,MATCH($C2,'Policy Characteristics'!$C:$C,0))) -> % of newly sold non-electric building components | P2: =IF(ISBLANK(INDEX('Policy Characteristics'!J:J,MATCH($C2,'Policy Characteristics'!$C:$C,0))),"",INDEX('Policy Characteristics'!J:J,MATCH($C2,'Policy Characteristics'!$C:$C,0))) -> **Description:** This policy replaces the specified fraction of newly sold non-electric building components of the selected type(s) in buildings of the selected type(s) with electricity-using components. | Q2: =IF(ISBLANK(INDEX('Policy Characteristics'!K:K,MATCH($C2,'Policy Characteristics'!$C:$C,0))),"",INDEX('Policy Characteristics'!K:K,MATCH($C2,'Policy Characteristics'!$C:$C,0))) -> buildings-sector-main.html#component-elec | R2: =IF(ISBLANK(INDEX('Policy Characteristics'!L:L,MATCH($C2,'Policy Characteristics'!$C:$C,0))),"",INDEX('Policy Characteristics'!L:L,MATCH($C2,'Policy Characteristics'!$C:$C,0))) -> building-component-electrification.html | S2: Increase the percentage of new building equipment sold that is electric.
A3: =IF(ISBLANK(INDEX('Policy Characteristics'!A:A,MATCH($C3,'Policy Characteristics'!$C:$C,0))),"",INDEX('Policy Characteristics'!A:A,MATCH($C3,'Policy Characteristics'!$C:$C,0))) -> Buildings and Appliances | B3: =IF(ISBLANK(INDEX('Policy Characteristics'!B:B,MATCH($C3,'Policy Characteristics'!$C:$C,0))),"",INDEX('Policy Characteristics'!B:B,MATCH($C3,'Policy Characteristics'!$C:$C,0))) -> Building Component Electrification | C3: Fraction of New Bldg Components Shifted to Other Fuels | D3: cooling and ventilation | E3: urban residential | F3: Cooling and Ventilation | G3: Urban Residential | H3: 436 | I3: No | J3: =IF(ISBLANK(INDEX('Policy Characteristics'!D:D,MATCH($C3,'Policy Characteristics'!$C:$C,0))),"",INDEX('Policy Characteristics'!D:D,MATCH($C3,'Policy Characteristics'!$C:$C,0))) -> Building Component Electrification | K3: =IF(ISBLANK(INDEX('Policy Characteristics'!E:E,MATCH($C3,'Policy Characteristics'!$C:$C,0))),"",INDEX('Policy Characteristics'!E:E,MATCH($C3,'Policy Characteristics'!$C:$C,0))) -> bldgs new component fuel shifting | L3: =IF(ISBLANK(INDEX('Policy Characteristics'!F:F,MATCH($C3,'Policy Characteristics'!$C:$C,0))),"",INDEX('Policy Characteristics'!F:F,MATCH($C3,'Policy Characteristics'!$C:$C,0))) -> 0 | M3: =IF(ISBLANK(INDEX('Policy Characteristics'!G:G,MATCH($C3,'Policy Characteristics'!$C:$C,0))),"",INDEX('Policy Characteristics'!G:G,MATCH($C3,'Policy Characteristics'!$C:$C,0))) -> 1 | N3: =IF(ISBLANK(INDEX('Policy Characteristics'!H:H,MATCH($C3,'Policy Characteristics'!$C:$C,0))),"",INDEX('Policy Characteristics'!H:H,MATCH($C3,'Policy Characteristics'!$C:$C,0))) -> 0.01 | O3: =IF(ISBLANK(INDEX('Policy Characteristics'!I:I,MATCH($C3,'Policy Characteristics'!$C:$C,0))),"",INDEX('Policy Characteristics'!I:I,MATCH($C3,'Policy Characteristics'!$C:$C,0))) -> % of newly sold non-electric building components | P3: =IF(ISBLANK(INDEX('Policy Characteristics'!J:J,MATCH($C3,'Policy Characteristics'!$C:$C,0))),"",INDEX('Policy Characteristics'!J:J,MATCH($C3,'Policy Characteristics'!$C:$C,0))) -> **Description:** This policy replaces the specified fraction of newly sold non-electric building components of the selected type(s) in buildings of the selected type(s) with electricity-using components. | Q3: =IF(ISBLANK(INDEX('Policy Characteristics'!K:K,MATCH($C3,'Policy Characteristics'!$C:$C,0))),"",INDEX('Policy Characteristics'!K:K,MATCH($C3,'Policy Characteristics'!$C:$C,0))) -> buildings-sector-main.html#component-elec | R3: =IF(ISBLANK(INDEX('Policy Characteristics'!L:L,MATCH($C3,'Policy Characteristics'!$C:$C,0))),"",INDEX('Policy Characteristics'!L:L,MATCH($C3,'Policy Characteristics'!$C:$C,0))) -> building-component-electrification.html
A4: =IF(ISBLANK(INDEX('Policy Characteristics'!A:A,MATCH($C4,'Policy Characteristics'!$C:$C,0))),"",INDEX('Policy Characteristics'!A:A,MATCH($C4,'Policy Characteristics'!$C:$C,0))) -> Buildings and Appliances | B4: =IF(ISBLANK(INDEX('Policy Characteristics'!B:B,MATCH($C4,'Policy Characteristics'!$C:$C,0))),"",INDEX('Policy Characteristics'!B:B,MATCH($C4,'Policy Characteristics'!$C:$C,0))) -> Building Component Electrification | C4: Fraction of New Bldg Components Shifted to Other Fuels | D4: lighting | E4: urban residential | F4: Lighting | G4: Urban Residential | H4: 437 | I4: No | J4: =IF(ISBLANK(INDEX('Policy Characteristics'!D:D,MATCH($C4,'Policy Characteristics'!$C:$C,0))),"",INDEX('Policy Characteristics'!D:D,MATCH($C4,'Policy Characteristics'!$C:$C,0))) -> Building Component Electrification | K4: =IF(ISBLANK(INDEX('Policy Characteristics'!E:E,MATCH($C4,'Policy Characteristics'!$C:$C,0))),"",INDEX('Policy Characteristics'!E:E,MATCH($C4,'Policy Characteristics'!$C:$C,0))) -> bldgs new component fuel shifting | L4: =IF(ISBLANK(INDEX('Policy Characteristics'!F:F,MATCH($C4,'Policy Characteristics'!$C:$C,0))),"",INDEX('Policy Characteristics'!F:F,MATCH($C4,'Policy Characteristics'!$C:$C,0))) -> 0 | M4: =IF(ISBLANK(INDEX('Policy Characteristics'!G:G,MATCH($C4,'Policy Characteristics'!$C:$C,0))),"",INDEX('Policy Characteristics'!G:G,MATCH($C4,'Policy Characteristics'!$C:$C,0))) -> 1 | N4: =IF(ISBLANK(INDEX('Policy Characteristics'!H:H,MATCH($C4,'Policy Characteristics'!$C:$C,0))),"",INDEX('Policy Characteristics'!H:H,MATCH($C4,'Policy Characteristics'!$C:$C,0))) -> 0.01 | O4: =IF(ISBLANK(INDEX('Policy Characteristics'!I:I,MATCH($C4,'Policy Characteristics'!$C:$C,0))),"",INDEX('Policy Characteristics'!I:I,MATCH($C4,'Policy Characteristics'!$C:$C,0))) -> % of newly sold non-electric building components | P4: =IF(ISBLANK(INDEX('Policy Characteristics'!J:J,MATCH($C4,'Policy Characteristics'!$C:$C,0))),"",INDEX('Policy Characteristics'!J:J,MATCH($C4,'Policy Characteristics'!$C:$C,0))) -> **Description:** This policy replaces the specified fraction of newly sold non-electric building components of the selected type(s) in buildings of the selected type(s) with electricity-using components. | Q4: =IF(ISBLANK(INDEX('Policy Characteristics'!K:K,MATCH($C4,'Policy Characteristics'!$C:$C,0))),"",INDEX('Policy Characteristics'!K:K,MATCH($C4,'Policy Characteristics'!$C:$C,0))) -> buildings-sector-main.html#component-elec | R4: =IF(ISBLANK(INDEX('Policy Characteristics'!L:L,MATCH($C4,'Policy Characteristics'!$C:$C,0))),"",INDEX('Policy Characteristics'!L:L,MATCH($C4,'Policy Characteristics'!$C:$C,0))) -> building-component-electrification.html
A5: =IF(ISBLANK(INDEX('Policy Characteristics'!A:A,MATCH($C5,'Policy Characteristics'!$C:$C,0))),"",INDEX('Policy Characteristics'!A:A,MATCH($C5,'Policy Characteristics'!$C:$C,0))) -> Buildings and Appliances | B5: =IF(ISBLANK(INDEX('Policy Characteristics'!B:B,MATCH($C5,'Policy Characteristics'!$C:$C,0))),"",INDEX('Policy Characteristics'!B:B,MATCH($C5,'Policy Characteristics'!$C:$C,0))) -> Building Component Electrification | C5: Fraction of New Bldg Components Shifted to Other Fuels | D5: appliances | E5: urban residential | F5: Appliances | G5: Urban Residential | H5: 438 | I5: Yes | J5: =IF(ISBLANK(INDEX('Policy Characteristics'!D:D,MATCH($C5,'Policy Characteristics'!$C:$C,0))),"",INDEX('Policy Characteristics'!D:D,MATCH($C5,'Policy Characteristics'!$C:$C,0))) -> Building Component Electrification | K5: =IF(ISBLANK(INDEX('Policy Characteristics'!E:E,MATCH($C5,'Policy Characteristics'!$C:$C,0))),"",INDEX('Policy Characteristics'!E:E,MATCH($C5,'Policy Characteristics'!$C:$C,0))) -> bldgs new component fuel shifting | L5: =IF(ISBLANK(INDEX('Policy Characteristics'!F:F,MATCH($C5,'Policy Characteristics'!$C:$C,0))),"",INDEX('Policy Characteristics'!F:F,MATCH($C5,'Policy Characteristics'!$C:$C,0))) -> 0 | M5: =IF(ISBLANK(INDEX('Policy Characteristics'!G:G,MATCH($C5,'Policy Characteristics'!$C:$C,0))),"",INDEX('Policy Characteristics'!G:G,MATCH($C5,'Policy Characteristics'!$C:$C,0))) -> 1 | N5: =IF(ISBLANK(INDEX('Policy Characteristics'!H:H,MATCH($C5,'Policy Characteristics'!$C:$C,0))),"",INDEX('Policy Characteristics'!H:H,MATCH($C5,'Policy Characteristics'!$C:$C,0))) -> 0.01 | O5: =IF(ISBLANK(INDEX('Policy Characteristics'!I:I,MATCH($C5,'Policy Characteristics'!$C:$C,0))),"",INDEX('Policy Characteristics'!I:I,MATCH($C5,'Policy Characteristics'!$C:$C,0))) -> % of newly sold non-electric building components | P5: =IF(ISBLANK(INDEX('Policy Characteristics'!J:J,MATCH($C5,'Policy Characteristics'!$C:$C,0))),"",INDEX('Policy Characteristics'!J:J,MATCH($C5,'Policy Characteristics'!$C:$C,0))) -> **Description:** This policy replaces the specified fraction of newly sold non-electric building components of the selected type(s) in buildings of the selected type(s) with electricity-using components. | Q5: =IF(ISBLANK(INDEX('Policy Characteristics'!K:K,MATCH($C5,'Policy Characteristics'!$C:$C,0))),"",INDEX('Policy Characteristics'!K:K,MATCH($C5,'Policy Characteristics'!$C:$C,0))) -> buildings-sector-main.html#component-elec | R5: =IF(ISBLANK(INDEX('Policy Characteristics'!L:L,MATCH($C5,'Policy Characteristics'!$C:$C,0))),"",INDEX('Policy Characteristics'!L:L,MATCH($C5,'Policy Characteristics'!$C:$C,0))) -> building-component-electrification.html
A6: =IF(ISBLANK(INDEX('Policy Characteristics'!A:A,MATCH($C6,'Policy Characteristics'!$C:$C,0))),"",INDEX('Policy Characteristics'!A:A,MATCH($C6,'Policy Characteristics'!$C:$C,0))) -> Buildings and Appliances | B6: =IF(ISBLANK(INDEX('Policy Characteristics'!B:B,MATCH($C6,'Policy Characteristics'!$C:$C,0))),"",INDEX('Policy Characteristics'!B:B,MATCH($C6,'Policy Characteristics'!$C:$C,0))) -> Building Component Electrification | C6: Fraction of New Bldg Components Shifted to Other Fuels | D6: other component | E6: urban residential | F6: Other Components | G6: Urban Residential | H6: 439 | I6: Yes | J6: =IF(ISBLANK(INDEX('Policy Characteristics'!D:D,MATCH($C6,'Policy Characteristics'!$C:$C,0))),"",INDEX('Policy Characteristics'!D:D,MATCH($C6,'Policy Characteristics'!$C:$C,0))) -> Building Component Electrification | K6: =IF(ISBLANK(INDEX('Policy Characteristics'!E:E,MATCH($C6,'Policy Characteristics'!$C:$C,0))),"",INDEX('Policy Characteristics'!E:E,MATCH($C6,'Policy Characteristics'!$C:$C,0))) -> bldgs new component fuel shifting | L6: =IF(ISBLANK(INDEX('Policy Characteristics'!F:F,MATCH($C6,'Policy Characteristics'!$C:$C,0))),"",INDEX('Policy Characteristics'!F:F,MATCH($C6,'Policy Characteristics'!$C:$C,0))) -> 0 | M6: =IF(ISBLANK(INDEX('Policy Characteristics'!G:G,MATCH($C6,'Policy Characteristics'!$C:$C,0))),"",INDEX('Policy Characteristics'!G:G,MATCH($C6,'Policy Characteristics'!$C:$C,0))) -> 1 | N6: =IF(ISBLANK(INDEX('Policy Characteristics'!H:H,MATCH($C6,'Policy Characteristics'!$C:$C,0))),"",INDEX('Policy Characteristics'!H:H,MATCH($C6,'Policy Characteristics'!$C:$C,0))) -> 0.01 | O6: =IF(ISBLANK(INDEX('Policy Characteristics'!I:I,MATCH($C6,'Policy Characteristics'!$C:$C,0))),"",INDEX('Policy Characteristics'!I:I,MATCH($C6,'Policy Characteristics'!$C:$C,0))) -> % of newly sold non-electric building components | P6: =IF(ISBLANK(INDEX('Policy Characteristics'!J:J,MATCH($C6,'Policy Characteristics'!$C:$C,0))),"",INDEX('Policy Characteristics'!J:J,MATCH($C6,'Policy Characteristics'!$C:$C,0))) -> **Description:** This policy replaces the specified fraction of newly sold non-electric building components of the selected type(s) in buildings of the selected type(s) with electricity-using components. | Q6: =IF(ISBLANK(INDEX('Policy Characteristics'!K:K,MATCH($C6,'Policy Characteristics'!$C:$C,0))),"",INDEX('Policy Characteristics'!K:K,MATCH($C6,'Policy Characteristics'!$C:$C,0))) -> buildings-sector-main.html#component-elec | R6: =IF(ISBLANK(INDEX('Policy Characteristics'!L:L,MATCH($C6,'Policy Characteristics'!$C:$C,0))),"",INDEX('Policy Characteristics'!L:L,MATCH($C6,'Policy Characteristics'!$C:$C,0))) -> building-component-electrification.html
A7: =IF(ISBLANK(INDEX('Policy Characteristics'!A:A,MATCH($C7,'Policy Characteristics'!$C:$C,0))),"",INDEX('Policy Characteristics'!A:A,MATCH($C7,'Policy Characteristics'!$C:$C,0))) -> Buildings and Appliances | B7: =IF(ISBLANK(INDEX('Policy Characteristics'!B:B,MATCH($C7,'Policy Characteristics'!$C:$C,0))),"",INDEX('Policy Characteristics'!B:B,MATCH($C7,'Policy Characteristics'!$C:$C,0))) -> Building Component Electrification | C7: Fraction of New Bldg Components Shifted to Other Fuels | D7: heating | E7: rural residential | F7: Heating | G7: Rural Residential | H7: 440 | I7: Yes | J7: =IF(ISBLANK(INDEX('Policy Characteristics'!D:D,MATCH($C7,'Policy Characteristics'!$C:$C,0))),"",INDEX('Policy Characteristics'!D:D,MATCH($C7,'Policy Characteristics'!$C:$C,0))) -> Building Component Electrification | K7: =IF(ISBLANK(INDEX('Policy Characteristics'!E:E,MATCH($C7,'Policy Characteristics'!$C:$C,0))),"",INDEX('Policy Characteristics'!E:E,MATCH($C7,'Policy Characteristics'!$C:$C,0))) -> bldgs new component fuel shifting | L7: =IF(ISBLANK(INDEX('Policy Characteristics'!F:F,MATCH($C7,'Policy Characteristics'!$C:$C,0))),"",INDEX('Policy Characteristics'!F:F,MATCH($C7,'Policy Characteristics'!$C:$C,0))) -> 0 | M7: =IF(ISBLANK(INDEX('Policy Characteristics'!G:G,MATCH($C7,'Policy Characteristics'!$C:$C,0))),"",INDEX('Policy Characteristics'!G:G,MATCH($C7,'Policy Characteristics'!$C:$C,0))) -> 1 | N7: =IF(ISBLANK(INDEX('Policy Characteristics'!H:H,MATCH($C7,'Policy Characteristics'!$C:$C,0))),"",INDEX('Policy Characteristics'!H:H,MATCH($C7,'Policy Characteristics'!$C:$C,0))) -> 0.01 | O7: =IF(ISBLANK(INDEX('Policy Characteristics'!I:I,MATCH($C7,'Policy Characteristics'!$C:$C,0))),"",INDEX('Policy Characteristics'!I:I,MATCH($C7,'Policy Characteristics'!$C:$C,0))) -> % of newly sold non-electric building components | P7: =IF(ISBLANK(INDEX('Policy Characteristics'!J:J,MATCH($C7,'Policy Characteristics'!$C:$C,0))),"",INDEX('Policy Characteristics'!J:J,MATCH($C7,'Policy Characteristics'!$C:$C,0))) -> **Description:** This policy replaces the specified fraction of newly sold non-electric building components of the selected type(s) in buildings of the selected type(s) with electricity-using components. | Q7: =IF(ISBLANK(INDEX('Policy Characteristics'!K:K,MATCH($C7,'Policy Characteristics'!$C:$C,0))),"",INDEX('Policy Characteristics'!K:K,MATCH($C7,'Policy Characteristics'!$C:$C,0))) -> buildings-sector-main.html#component-elec | R7: =IF(ISBLANK(INDEX('Policy Characteristics'!L:L,MATCH($C7,'Policy Characteristics'!$C:$C,0))),"",INDEX('Policy Characteristics'!L:L,MATCH($C7,'Policy Characteristics'!$C:$C,0))) -> building-component-electrification.html
A8: =IF(ISBLANK(INDEX('Policy Characteristics'!A:A,MATCH($C8,'Policy Characteristics'!$C:$C,0))),"",INDEX('Policy Characteristics'!A:A,MATCH($C8,'Policy Characteristics'!$C:$C,0))) -> Buildings and Appliances | B8: =IF(ISBLANK(INDEX('Policy Characteristics'!B:B,MATCH($C8,'Policy Characteristics'!$C:$C,0))),"",INDEX('Policy Characteristics'!B:B,MATCH($C8,'Policy Characteristics'!$C:$C,0))) -> Building Component Electrification | C8: Fraction of New Bldg Components Shifted to Other Fuels | D8: cooling and ventilation | E8: rural residential | F8: Cooling and Ventilation | G8: Rural Residential | H8: 441 | I8: No | J8: =IF(ISBLANK(INDEX('Policy Characteristics'!D:D,MATCH($C8,'Policy Characteristics'!$C:$C,0))),"",INDEX('Policy Characteristics'!D:D,MATCH($C8,'Policy Characteristics'!$C:$C,0))) -> Building Component Electrification | K8: =IF(ISBLANK(INDEX('Policy Characteristics'!E:E,MATCH($C8,'Policy Characteristics'!$C:$C,0))),"",INDEX('Policy Characteristics'!E:E,MATCH($C8,'Policy Characteristics'!$C:$C,0))) -> bldgs new component fuel shifting | L8: =IF(ISBLANK(INDEX('Policy Characteristics'!F:F,MATCH($C8,'Policy Characteristics'!$C:$C,0))),"",INDEX('Policy Characteristics'!F:F,MATCH($C8,'Policy Characteristics'!$C:$C,0))) -> 0 | M8: =IF(ISBLANK(INDEX('Policy Characteristics'!G:G,MATCH($C8,'Policy Characteristics'!$C:$C,0))),"",INDEX('Policy Characteristics'!G:G,MATCH($C8,'Policy Characteristics'!$C:$C,0))) -> 1 | N8: =IF(ISBLANK(INDEX('Policy Characteristics'!H:H,MATCH($C8,'Policy Characteristics'!$C:$C,0))),"",INDEX('Policy Characteristics'!H:H,MATCH($C8,'Policy Characteristics'!$C:$C,0))) -> 0.01 | O8: =IF(ISBLANK(INDEX('Policy Characteristics'!I:I,MATCH($C8,'Policy Characteristics'!$C:$C,0))),"",INDEX('Policy Characteristics'!I:I,MATCH($C8,'Policy Characteristics'!$C:$C,0))) -> % of newly sold non-electric building components | P8: =IF(ISBLANK(INDEX('Policy Characteristics'!J:J,MATCH($C8,'Policy Characteristics'!$C:$C,0))),"",INDEX('Policy Characteristics'!J:J,MATCH($C8,'Policy Characteristics'!$C:$C,0))) -> **Description:** This policy replaces the specified fraction of newly sold non-electric building components of the selected type(s) in buildings of the selected type(s) with electricity-using components. | Q8: =IF(ISBLANK(INDEX('Policy Characteristics'!K:K,MATCH($C8,'Policy Characteristics'!$C:$C,0))),"",INDEX('Policy Characteristics'!K:K,MATCH($C8,'Policy Characteristics'!$C:$C,0))) -> buildings-sector-main.html#component-elec | R8: =IF(ISBLANK(INDEX('Policy Characteristics'!L:L,MATCH($C8,'Policy Characteristics'!$C:$C,0))),"",INDEX('Policy Characteristics'!L:L,MATCH($C8,'Policy Characteristics'!$C:$C,0))) -> building-component-electrification.html
A9: =IF(ISBLANK(INDEX('Policy Characteristics'!A:A,MATCH($C9,'Policy Characteristics'!$C:$C,0))),"",INDEX('Policy Characteristics'!A:A,MATCH($C9,'Policy Characteristics'!$C:$C,0))) -> Buildings and Appliances | B9: =IF(ISBLANK(INDEX('Policy Characteristics'!B:B,MATCH($C9,'Policy Characteristics'!$C:$C,0))),"",INDEX('Policy Characteristics'!B:B,MATCH($C9,'Policy Characteristics'!$C:$C,0))) -> Building Component Electrification | C9: Fraction of New Bldg Components Shifted to Other Fuels | D9: lighting | E9: rural residential | F9: Lighting | G9: Rural Residential | H9: 442 | I9: No | J9: =IF(ISBLANK(INDEX('Policy Characteristics'!D:D,MATCH($C9,'Policy Characteristics'!$C:$C,0))),"",INDEX('Policy Characteristics'!D:D,MATCH($C9,'Policy Characteristics'!$C:$C,0))) -> Building Component Electrification | K9: =IF(ISBLANK(INDEX('Policy Characteristics'!E:E,MATCH($C9,'Policy Characteristics'!$C:$C,0))),"",INDEX('Policy Characteristics'!E:E,MATCH($C9,'Policy Characteristics'!$C:$C,0))) -> bldgs new component fuel shifting | L9: =IF(ISBLANK(INDEX('Policy Characteristics'!F:F,MATCH($C9,'Policy Characteristics'!$C:$C,0))),"",INDEX('Policy Characteristics'!F:F,MATCH($C9,'Policy Characteristics'!$C:$C,0))) -> 0 | M9: =IF(ISBLANK(INDEX('Policy Characteristics'!G:G,MATCH($C9,'Policy Characteristics'!$C:$C,0))),"",INDEX('Policy Characteristics'!G:G,MATCH($C9,'Policy Characteristics'!$C:$C,0))) -> 1 | N9: =IF(ISBLANK(INDEX('Policy Characteristics'!H:H,MATCH($C9,'Policy Characteristics'!$C:$C,0))),"",INDEX('Policy Characteristics'!H:H,MATCH($C9,'Policy Characteristics'!$C:$C,0))) -> 0.01 | O9: =IF(ISBLANK(INDEX('Policy Characteristics'!I:I,MATCH($C9,'Policy Characteristics'!$C:$C,0))),"",INDEX('Policy Characteristics'!I:I,MATCH($C9,'Policy Characteristics'!$C:$C,0))) -> % of newly sold non-electric building components | P9: =IF(ISBLANK(INDEX('Policy Characteristics'!J:J,MATCH($C9,'Policy Characteristics'!$C:$C,0))),"",INDEX('Policy Characteristics'!J:J,MATCH($C9,'Policy Characteristics'!$C:$C,0))) -> **Description:** This policy replaces the specified fraction of newly sold non-electric building components of the selected type(s) in buildings of the selected type(s) with electricity-using components. | Q9: =IF(ISBLANK(INDEX('Policy Characteristics'!K:K,MATCH($C9,'Policy Characteristics'!$C:$C,0))),"",INDEX('Policy Characteristics'!K:K,MATCH($C9,'Policy Characteristics'!$C:$C,0))) -> buildings-sector-main.html#component-elec | R9: =IF(ISBLANK(INDEX('Policy Characteristics'!L:L,MATCH($C9,'Policy Characteristics'!$C:$C,0))),"",INDEX('Policy Characteristics'!L:L,MATCH($C9,'Policy Characteristics'!$C:$C,0))) -> building-component-electrification.html
A10: =IF(ISBLANK(INDEX('Policy Characteristics'!A:A,MATCH($C10,'Policy Characteristics'!$C:$C,0))),"",INDEX('Policy Characteristics'!A:A,MATCH($C10,'Policy Characteristics'!$C:$C,0))) -> Buildings and Appliances | B10: =IF(ISBLANK(INDEX('Policy Characteristics'!B:B,MATCH($C10,'Policy Characteristics'!$C:$C,0))),"",INDEX('Policy Characteristics'!B:B,MATCH($C10,'Policy Characteristics'!$C:$C,0))) -> Building Component Electrification | C10: Fraction of New Bldg Components Shifted to Other Fuels | D10: appliances | E10: rural residential | F10: Appliances | G10: Rural Residential | H10: 443 | I10: Yes | J10: =IF(ISBLANK(INDEX('Policy Characteristics'!D:D,MATCH($C10,'Policy Characteristics'!$C:$C,0))),"",INDEX('Policy Characteristics'!D:D,MATCH($C10,'Policy Characteristics'!$C:$C,0))) -> Building Component Electrification | K10: =IF(ISBLANK(INDEX('Policy Characteristics'!E:E,MATCH($C10,'Policy Characteristics'!$C:$C,0))),"",INDEX('Policy Characteristics'!E:E,MATCH($C10,'Policy Characteristics'!$C:$C,0))) -> bldgs new component fuel shifting | L10: =IF(ISBLANK(INDEX('Policy Characteristics'!F:F,MATCH($C10,'Policy Characteristics'!$C:$C,0))),"",INDEX('Policy Characteristics'!F:F,MATCH($C10,'Policy Characteristics'!$C:$C,0))) -> 0 | M10: =IF(ISBLANK(INDEX('Policy Characteristics'!G:G,MATCH($C10,'Policy Characteristics'!$C:$C,0))),"",INDEX('Policy Characteristics'!G:G,MATCH($C10,'Policy Characteristics'!$C:$C,0))) -> 1 | N10: =IF(ISBLANK(INDEX('Policy Characteristics'!H:H,MATCH($C10,'Policy Characteristics'!$C:$C,0))),"",INDEX('Policy Characteristics'!H:H,MATCH($C10,'Policy Characteristics'!$C:$C,0))) -> 0.01 | O10: =IF(ISBLANK(INDEX('Policy Characteristics'!I:I,MATCH($C10,'Policy Characteristics'!$C:$C,0))),"",INDEX('Policy Characteristics'!I:I,MATCH($C10,'Policy Characteristics'!$C:$C,0))) -> % of newly sold non-electric building components | P10: =IF(ISBLANK(INDEX('Policy Characteristics'!J:J,MATCH($C10,'Policy Characteristics'!$C:$C,0))),"",INDEX('Policy Characteristics'!J:J,MATCH($C10,'Policy Characteristics'!$C:$C,0))) -> **Description:** This policy replaces the specified fraction of newly sold non-electric building components of the selected type(s) in buildings of the selected type(s) with electricity-using components. | Q10: =IF(ISBLANK(INDEX('Policy Characteristics'!K:K,MATCH($C10,'Policy Characteristics'!$C:$C,0))),"",INDEX('Policy Characteristics'!K:K,MATCH($C10,'Policy Characteristics'!$C:$C,0))) -> buildings-sector-main.html#component-elec | R10: =IF(ISBLANK(INDEX('Policy Characteristics'!L:L,MATCH($C10,'Policy Characteristics'!$C:$C,0))),"",INDEX('Policy Characteristics'!L:L,MATCH($C10,'Policy Characteristics'!$C:$C,0))) -> building-component-electrification.html
